{
  "cells": [
    {
      "cell_type": "code",
      "execution_count": null,
      "metadata": {
        "colab": {
          "base_uri": "https://localhost:8080/"
        },
        "id": "1UV4_8y2Qzxw",
        "outputId": "e6112528-8591-4b25-f91c-9bcc286837e0"
      },
      "outputs": [
        {
          "name": "stdout",
          "output_type": "stream",
          "text": [
            "Python 3.10.11\n"
          ]
        }
      ],
      "source": [
        "!python3 --version"
      ]
    },
    {
      "cell_type": "code",
      "execution_count": null,
      "metadata": {
        "colab": {
          "base_uri": "https://localhost:8080/"
        },
        "id": "_ROnzcSvQ1lL",
        "outputId": "5bb0a2d9-0caf-4522-bb38-d3fee0701952"
      },
      "outputs": [
        {
          "name": "stdout",
          "output_type": "stream",
          "text": [
            "Looking in indexes: https://pypi.org/simple, https://us-python.pkg.dev/colab-wheels/public/simple/\n",
            "Collecting pytelegrambotapi\n",
            "  Downloading pyTelegramBotAPI-4.11.0.tar.gz (230 kB)\n",
            "\u001b[2K     \u001b[90m━━━━━━━━━━━━━━━━━━━━━━━━━━━━━━━━━━━━━━━\u001b[0m \u001b[32m230.4/230.4 kB\u001b[0m \u001b[31m5.2 MB/s\u001b[0m eta \u001b[36m0:00:00\u001b[0m\n",
            "\u001b[?25h  Preparing metadata (setup.py) ... \u001b[?25l\u001b[?25hdone\n",
            "Requirement already satisfied: requests in /usr/local/lib/python3.10/dist-packages (from pytelegrambotapi) (2.27.1)\n",
            "Requirement already satisfied: urllib3<1.27,>=1.21.1 in /usr/local/lib/python3.10/dist-packages (from requests->pytelegrambotapi) (1.26.15)\n",
            "Requirement already satisfied: idna<4,>=2.5 in /usr/local/lib/python3.10/dist-packages (from requests->pytelegrambotapi) (3.4)\n",
            "Requirement already satisfied: certifi>=2017.4.17 in /usr/local/lib/python3.10/dist-packages (from requests->pytelegrambotapi) (2022.12.7)\n",
            "Requirement already satisfied: charset-normalizer~=2.0.0 in /usr/local/lib/python3.10/dist-packages (from requests->pytelegrambotapi) (2.0.12)\n",
            "Building wheels for collected packages: pytelegrambotapi\n",
            "  Building wheel for pytelegrambotapi (setup.py) ... \u001b[?25l\u001b[?25hdone\n",
            "  Created wheel for pytelegrambotapi: filename=pyTelegramBotAPI-4.11.0-py3-none-any.whl size=212399 sha256=83f3d9b235e38551c7d0fe0f02ec18910f55b068b68b3a68d44ed516a50cec57\n",
            "  Stored in directory: /root/.cache/pip/wheels/ee/54/14/73e9f99d3a4c02df8d106566f93bd29d41ab7f3915cc13a23d\n",
            "Successfully built pytelegrambotapi\n",
            "Installing collected packages: pytelegrambotapi\n",
            "Successfully installed pytelegrambotapi-4.11.0\n"
          ]
        }
      ],
      "source": [
        "!pip3 install pytelegrambotapi"
      ]
    },
    {
      "cell_type": "code",
      "execution_count": null,
      "metadata": {
        "colab": {
          "base_uri": "https://localhost:8080/"
        },
        "id": "9uOPpoH8Q8UI",
        "outputId": "a6872f62-30c9-4db1-c275-cbb8ed844841"
      },
      "outputs": [
        {
          "name": "stdout",
          "output_type": "stream",
          "text": [
            "Looking in indexes: https://pypi.org/simple, https://us-python.pkg.dev/colab-wheels/public/simple/\n",
            "Requirement already satisfied: wikipedia in /usr/local/lib/python3.10/dist-packages (1.4.0)\n",
            "Requirement already satisfied: requests<3.0.0,>=2.0.0 in /usr/local/lib/python3.10/dist-packages (from wikipedia) (2.27.1)\n",
            "Requirement already satisfied: beautifulsoup4 in /usr/local/lib/python3.10/dist-packages (from wikipedia) (4.11.2)\n",
            "Requirement already satisfied: charset-normalizer~=2.0.0 in /usr/local/lib/python3.10/dist-packages (from requests<3.0.0,>=2.0.0->wikipedia) (2.0.12)\n",
            "Requirement already satisfied: urllib3<1.27,>=1.21.1 in /usr/local/lib/python3.10/dist-packages (from requests<3.0.0,>=2.0.0->wikipedia) (1.26.15)\n",
            "Requirement already satisfied: idna<4,>=2.5 in /usr/local/lib/python3.10/dist-packages (from requests<3.0.0,>=2.0.0->wikipedia) (3.4)\n",
            "Requirement already satisfied: certifi>=2017.4.17 in /usr/local/lib/python3.10/dist-packages (from requests<3.0.0,>=2.0.0->wikipedia) (2022.12.7)\n",
            "Requirement already satisfied: soupsieve>1.2 in /usr/local/lib/python3.10/dist-packages (from beautifulsoup4->wikipedia) (2.4.1)\n"
          ]
        }
      ],
      "source": [
        "!pip3 install wikipedia-API\n",
        "\n"
      ]
    },
    {
      "cell_type": "code",
      "execution_count": null,
      "metadata": {
        "id": "8V6WLuMXQRW_"
      },
      "outputs": [],
      "source": [
        "import telebot, wikipedia, re"
      ]
    },
    {
      "cell_type": "code",
      "execution_count": null,
      "metadata": {
        "id": "wSc3J_4_QSnO"
      },
      "outputs": [],
      "source": [
        "bot = telebot.TeleBot('')"
      ]
    },
    {
      "cell_type": "code",
      "execution_count": null,
      "metadata": {
        "id": "_xP9tysjbQwN"
      },
      "outputs": [],
      "source": [
        "from telebot import types"
      ]
    },
    {
      "cell_type": "code",
      "execution_count": null,
      "metadata": {
        "id": "6rwUP-ykdt-m"
      },
      "outputs": [],
      "source": [
        "@bot.message_handler(commands = ['start'])\n",
        "def url(message):\n",
        "    markup = types.InlineKeyboardMarkup()\n",
        "    btn1 = types.InlineKeyboardButton(text='Русский словарь', url='https://ru.m.wiktionary.org/wiki/')\n",
        "    markup.add(btn1)\n",
        "    bot.send_message(message.from_user.id, \"Привет , меня зовут Wiki! Если ты хочешь перейти в Русский Викисловарь, нажми на кнопку  ниже. Или введи любое слово чтобы узнать что это такое из энциклопедии! \", reply_markup = markup)"
      ]
    },
    {
      "cell_type": "code",
      "execution_count": null,
      "metadata": {
        "id": "f5spv3jrQe6f"
      },
      "outputs": [],
      "source": [
        "wikipedia.set_lang(\"ru\")"
      ]
    },
    {
      "cell_type": "code",
      "execution_count": null,
      "metadata": {
        "id": "pG87Jny_KR_g"
      },
      "outputs": [],
      "source": [
        "from dataclasses import dataclass\n",
        "\n",
        "@dataclass\n",
        "class Employee:\n",
        "    name: str\n",
        "    dept: str\n",
        "    salary: int\n",
        "\n"
      ]
    },
    {
      "cell_type": "code",
      "execution_count": null,
      "metadata": {
        "colab": {
          "background_save": true,
          "base_uri": "https://localhost:8080/"
        },
        "id": "K0MgxHUgQjBO",
        "outputId": "7ef2f46f-1255-438a-a099-ba65d3c63868"
      },
      "outputs": [
        {
          "name": "stderr",
          "output_type": "stream",
          "text": [
            "2023-05-04 13:42:48,618 (__init__.py:1083 MainThread) ERROR - TeleBot: \"Threaded polling exception: A request to the Telegram API was unsuccessful. Error code: 403. Description: Forbidden: bot can't send messages to bots\"\n",
            "ERROR:TeleBot:Threaded polling exception: A request to the Telegram API was unsuccessful. Error code: 403. Description: Forbidden: bot can't send messages to bots\n",
            "2023-05-04 13:42:48,621 (__init__.py:1085 MainThread) ERROR - TeleBot: \"Exception traceback:\n",
            "Traceback (most recent call last):\n",
            "  File \"/usr/local/lib/python3.10/dist-packages/telebot/__init__.py\", line 1074, in __threaded_polling\n",
            "    self.worker_pool.raise_exceptions()\n",
            "  File \"/usr/local/lib/python3.10/dist-packages/telebot/util.py\", line 147, in raise_exceptions\n",
            "    raise self.exception_info\n",
            "  File \"/usr/local/lib/python3.10/dist-packages/telebot/util.py\", line 90, in run\n",
            "    task(*args, **kwargs)\n",
            "  File \"/usr/local/lib/python3.10/dist-packages/telebot/__init__.py\", line 6720, in _run_middlewares_and_handler\n",
            "    result = handler['function'](message)\n",
            "  File \"<ipython-input-8-7f795ddbf42d>\", line 6, in url\n",
            "    bot.send_message(message.from_user.id, \"Привет , меня зовут Wiki! Если ты хочешь перейти в Русский Викисловарь, нажми на кнопку  ниже. Или введи любое слово чтобы узнать что это такое из энциклопедии! \", reply_markup = markup)\n",
            "  File \"/usr/local/lib/python3.10/dist-packages/telebot/__init__.py\", line 1549, in send_message\n",
            "    apihelper.send_message(\n",
            "  File \"/usr/local/lib/python3.10/dist-packages/telebot/apihelper.py\", line 264, in send_message\n",
            "    return _make_request(token, method_url, params=payload, method='post')\n",
            "  File \"/usr/local/lib/python3.10/dist-packages/telebot/apihelper.py\", line 162, in _make_request\n",
            "    json_result = _check_result(method_name, result)\n",
            "  File \"/usr/local/lib/python3.10/dist-packages/telebot/apihelper.py\", line 189, in _check_result\n",
            "    raise ApiTelegramException(method_name, result, result_json)\n",
            "telebot.apihelper.ApiTelegramException: A request to the Telegram API was unsuccessful. Error code: 403. Description: Forbidden: bot can't send messages to bots\n",
            "\"\n",
            "ERROR:TeleBot:Exception traceback:\n",
            "Traceback (most recent call last):\n",
            "  File \"/usr/local/lib/python3.10/dist-packages/telebot/__init__.py\", line 1074, in __threaded_polling\n",
            "    self.worker_pool.raise_exceptions()\n",
            "  File \"/usr/local/lib/python3.10/dist-packages/telebot/util.py\", line 147, in raise_exceptions\n",
            "    raise self.exception_info\n",
            "  File \"/usr/local/lib/python3.10/dist-packages/telebot/util.py\", line 90, in run\n",
            "    task(*args, **kwargs)\n",
            "  File \"/usr/local/lib/python3.10/dist-packages/telebot/__init__.py\", line 6720, in _run_middlewares_and_handler\n",
            "    result = handler['function'](message)\n",
            "  File \"<ipython-input-8-7f795ddbf42d>\", line 6, in url\n",
            "    bot.send_message(message.from_user.id, \"Привет , меня зовут Wiki! Если ты хочешь перейти в Русский Викисловарь, нажми на кнопку  ниже. Или введи любое слово чтобы узнать что это такое из энциклопедии! \", reply_markup = markup)\n",
            "  File \"/usr/local/lib/python3.10/dist-packages/telebot/__init__.py\", line 1549, in send_message\n",
            "    apihelper.send_message(\n",
            "  File \"/usr/local/lib/python3.10/dist-packages/telebot/apihelper.py\", line 264, in send_message\n",
            "    return _make_request(token, method_url, params=payload, method='post')\n",
            "  File \"/usr/local/lib/python3.10/dist-packages/telebot/apihelper.py\", line 162, in _make_request\n",
            "    json_result = _check_result(method_name, result)\n",
            "  File \"/usr/local/lib/python3.10/dist-packages/telebot/apihelper.py\", line 189, in _check_result\n",
            "    raise ApiTelegramException(method_name, result, result_json)\n",
            "telebot.apihelper.ApiTelegramException: A request to the Telegram API was unsuccessful. Error code: 403. Description: Forbidden: bot can't send messages to bots\n",
            "\n",
            "2023-05-04 13:42:48,885 (__init__.py:1083 MainThread) ERROR - TeleBot: \"Threaded polling exception: A request to the Telegram API was unsuccessful. Error code: 403. Description: Forbidden: bot can't initiate conversation with a user\"\n",
            "ERROR:TeleBot:Threaded polling exception: A request to the Telegram API was unsuccessful. Error code: 403. Description: Forbidden: bot can't initiate conversation with a user\n",
            "2023-05-04 13:42:48,898 (__init__.py:1085 MainThread) ERROR - TeleBot: \"Exception traceback:\n",
            "Traceback (most recent call last):\n",
            "  File \"/usr/local/lib/python3.10/dist-packages/telebot/__init__.py\", line 1074, in __threaded_polling\n",
            "    self.worker_pool.raise_exceptions()\n",
            "  File \"/usr/local/lib/python3.10/dist-packages/telebot/util.py\", line 147, in raise_exceptions\n",
            "    raise self.exception_info\n",
            "  File \"/usr/local/lib/python3.10/dist-packages/telebot/util.py\", line 90, in run\n",
            "    task(*args, **kwargs)\n",
            "  File \"/usr/local/lib/python3.10/dist-packages/telebot/__init__.py\", line 6720, in _run_middlewares_and_handler\n",
            "    result = handler['function'](message)\n",
            "  File \"<ipython-input-8-7f795ddbf42d>\", line 6, in url\n",
            "    bot.send_message(message.from_user.id, \"Привет , меня зовут Wiki! Если ты хочешь перейти в Русский Викисловарь, нажми на кнопку  ниже. Или введи любое слово чтобы узнать что это такое из энциклопедии! \", reply_markup = markup)\n",
            "  File \"/usr/local/lib/python3.10/dist-packages/telebot/__init__.py\", line 1549, in send_message\n",
            "    apihelper.send_message(\n",
            "  File \"/usr/local/lib/python3.10/dist-packages/telebot/apihelper.py\", line 264, in send_message\n",
            "    return _make_request(token, method_url, params=payload, method='post')\n",
            "  File \"/usr/local/lib/python3.10/dist-packages/telebot/apihelper.py\", line 162, in _make_request\n",
            "    json_result = _check_result(method_name, result)\n",
            "  File \"/usr/local/lib/python3.10/dist-packages/telebot/apihelper.py\", line 189, in _check_result\n",
            "    raise ApiTelegramException(method_name, result, result_json)\n",
            "telebot.apihelper.ApiTelegramException: A request to the Telegram API was unsuccessful. Error code: 403. Description: Forbidden: bot can't initiate conversation with a user\n",
            "\"\n",
            "ERROR:TeleBot:Exception traceback:\n",
            "Traceback (most recent call last):\n",
            "  File \"/usr/local/lib/python3.10/dist-packages/telebot/__init__.py\", line 1074, in __threaded_polling\n",
            "    self.worker_pool.raise_exceptions()\n",
            "  File \"/usr/local/lib/python3.10/dist-packages/telebot/util.py\", line 147, in raise_exceptions\n",
            "    raise self.exception_info\n",
            "  File \"/usr/local/lib/python3.10/dist-packages/telebot/util.py\", line 90, in run\n",
            "    task(*args, **kwargs)\n",
            "  File \"/usr/local/lib/python3.10/dist-packages/telebot/__init__.py\", line 6720, in _run_middlewares_and_handler\n",
            "    result = handler['function'](message)\n",
            "  File \"<ipython-input-8-7f795ddbf42d>\", line 6, in url\n",
            "    bot.send_message(message.from_user.id, \"Привет , меня зовут Wiki! Если ты хочешь перейти в Русский Викисловарь, нажми на кнопку  ниже. Или введи любое слово чтобы узнать что это такое из энциклопедии! \", reply_markup = markup)\n",
            "  File \"/usr/local/lib/python3.10/dist-packages/telebot/__init__.py\", line 1549, in send_message\n",
            "    apihelper.send_message(\n",
            "  File \"/usr/local/lib/python3.10/dist-packages/telebot/apihelper.py\", line 264, in send_message\n",
            "    return _make_request(token, method_url, params=payload, method='post')\n",
            "  File \"/usr/local/lib/python3.10/dist-packages/telebot/apihelper.py\", line 162, in _make_request\n",
            "    json_result = _check_result(method_name, result)\n",
            "  File \"/usr/local/lib/python3.10/dist-packages/telebot/apihelper.py\", line 189, in _check_result\n",
            "    raise ApiTelegramException(method_name, result, result_json)\n",
            "telebot.apihelper.ApiTelegramException: A request to the Telegram API was unsuccessful. Error code: 403. Description: Forbidden: bot can't initiate conversation with a user\n",
            "\n",
            "2023-05-04 13:43:16,539 (__init__.py:1083 MainThread) ERROR - TeleBot: \"Threaded polling exception: A request to the Telegram API was unsuccessful. Error code: 403. Description: Forbidden: bot can't send messages to bots\"\n",
            "ERROR:TeleBot:Threaded polling exception: A request to the Telegram API was unsuccessful. Error code: 403. Description: Forbidden: bot can't send messages to bots\n",
            "2023-05-04 13:43:16,542 (__init__.py:1085 MainThread) ERROR - TeleBot: \"Exception traceback:\n",
            "Traceback (most recent call last):\n",
            "  File \"/usr/local/lib/python3.10/dist-packages/telebot/__init__.py\", line 1074, in __threaded_polling\n",
            "    self.worker_pool.raise_exceptions()\n",
            "  File \"/usr/local/lib/python3.10/dist-packages/telebot/util.py\", line 147, in raise_exceptions\n",
            "    raise self.exception_info\n",
            "  File \"/usr/local/lib/python3.10/dist-packages/telebot/util.py\", line 90, in run\n",
            "    task(*args, **kwargs)\n",
            "  File \"/usr/local/lib/python3.10/dist-packages/telebot/__init__.py\", line 6720, in _run_middlewares_and_handler\n",
            "    result = handler['function'](message)\n",
            "  File \"<ipython-input-8-7f795ddbf42d>\", line 6, in url\n",
            "    bot.send_message(message.from_user.id, \"Привет , меня зовут Wiki! Если ты хочешь перейти в Русский Викисловарь, нажми на кнопку  ниже. Или введи любое слово чтобы узнать что это такое из энциклопедии! \", reply_markup = markup)\n",
            "  File \"/usr/local/lib/python3.10/dist-packages/telebot/__init__.py\", line 1549, in send_message\n",
            "    apihelper.send_message(\n",
            "  File \"/usr/local/lib/python3.10/dist-packages/telebot/apihelper.py\", line 264, in send_message\n",
            "    return _make_request(token, method_url, params=payload, method='post')\n",
            "  File \"/usr/local/lib/python3.10/dist-packages/telebot/apihelper.py\", line 162, in _make_request\n",
            "    json_result = _check_result(method_name, result)\n",
            "  File \"/usr/local/lib/python3.10/dist-packages/telebot/apihelper.py\", line 189, in _check_result\n",
            "    raise ApiTelegramException(method_name, result, result_json)\n",
            "telebot.apihelper.ApiTelegramException: A request to the Telegram API was unsuccessful. Error code: 403. Description: Forbidden: bot can't send messages to bots\n",
            "\"\n",
            "ERROR:TeleBot:Exception traceback:\n",
            "Traceback (most recent call last):\n",
            "  File \"/usr/local/lib/python3.10/dist-packages/telebot/__init__.py\", line 1074, in __threaded_polling\n",
            "    self.worker_pool.raise_exceptions()\n",
            "  File \"/usr/local/lib/python3.10/dist-packages/telebot/util.py\", line 147, in raise_exceptions\n",
            "    raise self.exception_info\n",
            "  File \"/usr/local/lib/python3.10/dist-packages/telebot/util.py\", line 90, in run\n",
            "    task(*args, **kwargs)\n",
            "  File \"/usr/local/lib/python3.10/dist-packages/telebot/__init__.py\", line 6720, in _run_middlewares_and_handler\n",
            "    result = handler['function'](message)\n",
            "  File \"<ipython-input-8-7f795ddbf42d>\", line 6, in url\n",
            "    bot.send_message(message.from_user.id, \"Привет , меня зовут Wiki! Если ты хочешь перейти в Русский Викисловарь, нажми на кнопку  ниже. Или введи любое слово чтобы узнать что это такое из энциклопедии! \", reply_markup = markup)\n",
            "  File \"/usr/local/lib/python3.10/dist-packages/telebot/__init__.py\", line 1549, in send_message\n",
            "    apihelper.send_message(\n",
            "  File \"/usr/local/lib/python3.10/dist-packages/telebot/apihelper.py\", line 264, in send_message\n",
            "    return _make_request(token, method_url, params=payload, method='post')\n",
            "  File \"/usr/local/lib/python3.10/dist-packages/telebot/apihelper.py\", line 162, in _make_request\n",
            "    json_result = _check_result(method_name, result)\n",
            "  File \"/usr/local/lib/python3.10/dist-packages/telebot/apihelper.py\", line 189, in _check_result\n",
            "    raise ApiTelegramException(method_name, result, result_json)\n",
            "telebot.apihelper.ApiTelegramException: A request to the Telegram API was unsuccessful. Error code: 403. Description: Forbidden: bot can't send messages to bots\n",
            "\n",
            "/usr/local/lib/python3.10/dist-packages/wikipedia/wikipedia.py:389: GuessedAtParserWarning: No parser was explicitly specified, so I'm using the best available HTML parser for this system (\"lxml\"). This usually isn't a problem, but if you run this code on another system, or in a different virtual environment, it may use a different parser and behave differently.\n",
            "\n",
            "The code that caused this warning is on line 389 of the file /usr/local/lib/python3.10/dist-packages/wikipedia/wikipedia.py. To get rid of this warning, pass the additional argument 'features=\"lxml\"' to the BeautifulSoup constructor.\n",
            "\n",
            "  lis = BeautifulSoup(html).find_all('li')\n",
            "2023-05-04 15:01:20,275 (__init__.py:1083 MainThread) ERROR - TeleBot: \"Threaded polling exception: A request to the Telegram API was unsuccessful. Error code: 403. Description: Forbidden: bot can't initiate conversation with a user\"\n",
            "ERROR:TeleBot:Threaded polling exception: A request to the Telegram API was unsuccessful. Error code: 403. Description: Forbidden: bot can't initiate conversation with a user\n",
            "2023-05-04 15:01:20,278 (__init__.py:1085 MainThread) ERROR - TeleBot: \"Exception traceback:\n",
            "Traceback (most recent call last):\n",
            "  File \"/usr/local/lib/python3.10/dist-packages/telebot/__init__.py\", line 1074, in __threaded_polling\n",
            "    self.worker_pool.raise_exceptions()\n",
            "  File \"/usr/local/lib/python3.10/dist-packages/telebot/util.py\", line 147, in raise_exceptions\n",
            "    raise self.exception_info\n",
            "  File \"/usr/local/lib/python3.10/dist-packages/telebot/util.py\", line 90, in run\n",
            "    task(*args, **kwargs)\n",
            "  File \"/usr/local/lib/python3.10/dist-packages/telebot/__init__.py\", line 6720, in _run_middlewares_and_handler\n",
            "    result = handler['function'](message)\n",
            "  File \"<ipython-input-8-7f795ddbf42d>\", line 6, in url\n",
            "    bot.send_message(message.from_user.id, \"Привет , меня зовут Wiki! Если ты хочешь перейти в Русский Викисловарь, нажми на кнопку  ниже. Или введи любое слово чтобы узнать что это такое из энциклопедии! \", reply_markup = markup)\n",
            "  File \"/usr/local/lib/python3.10/dist-packages/telebot/__init__.py\", line 1549, in send_message\n",
            "    apihelper.send_message(\n",
            "  File \"/usr/local/lib/python3.10/dist-packages/telebot/apihelper.py\", line 264, in send_message\n",
            "    return _make_request(token, method_url, params=payload, method='post')\n",
            "  File \"/usr/local/lib/python3.10/dist-packages/telebot/apihelper.py\", line 162, in _make_request\n",
            "    json_result = _check_result(method_name, result)\n",
            "  File \"/usr/local/lib/python3.10/dist-packages/telebot/apihelper.py\", line 189, in _check_result\n",
            "    raise ApiTelegramException(method_name, result, result_json)\n",
            "telebot.apihelper.ApiTelegramException: A request to the Telegram API was unsuccessful. Error code: 403. Description: Forbidden: bot can't initiate conversation with a user\n",
            "\"\n",
            "ERROR:TeleBot:Exception traceback:\n",
            "Traceback (most recent call last):\n",
            "  File \"/usr/local/lib/python3.10/dist-packages/telebot/__init__.py\", line 1074, in __threaded_polling\n",
            "    self.worker_pool.raise_exceptions()\n",
            "  File \"/usr/local/lib/python3.10/dist-packages/telebot/util.py\", line 147, in raise_exceptions\n",
            "    raise self.exception_info\n",
            "  File \"/usr/local/lib/python3.10/dist-packages/telebot/util.py\", line 90, in run\n",
            "    task(*args, **kwargs)\n",
            "  File \"/usr/local/lib/python3.10/dist-packages/telebot/__init__.py\", line 6720, in _run_middlewares_and_handler\n",
            "    result = handler['function'](message)\n",
            "  File \"<ipython-input-8-7f795ddbf42d>\", line 6, in url\n",
            "    bot.send_message(message.from_user.id, \"Привет , меня зовут Wiki! Если ты хочешь перейти в Русский Викисловарь, нажми на кнопку  ниже. Или введи любое слово чтобы узнать что это такое из энциклопедии! \", reply_markup = markup)\n",
            "  File \"/usr/local/lib/python3.10/dist-packages/telebot/__init__.py\", line 1549, in send_message\n",
            "    apihelper.send_message(\n",
            "  File \"/usr/local/lib/python3.10/dist-packages/telebot/apihelper.py\", line 264, in send_message\n",
            "    return _make_request(token, method_url, params=payload, method='post')\n",
            "  File \"/usr/local/lib/python3.10/dist-packages/telebot/apihelper.py\", line 162, in _make_request\n",
            "    json_result = _check_result(method_name, result)\n",
            "  File \"/usr/local/lib/python3.10/dist-packages/telebot/apihelper.py\", line 189, in _check_result\n",
            "    raise ApiTelegramException(method_name, result, result_json)\n",
            "telebot.apihelper.ApiTelegramException: A request to the Telegram API was unsuccessful. Error code: 403. Description: Forbidden: bot can't initiate conversation with a user\n",
            "\n",
            "2023-05-04 15:01:47,565 (__init__.py:1083 MainThread) ERROR - TeleBot: \"Threaded polling exception: A request to the Telegram API was unsuccessful. Error code: 403. Description: Forbidden: bot can't initiate conversation with a user\"\n",
            "ERROR:TeleBot:Threaded polling exception: A request to the Telegram API was unsuccessful. Error code: 403. Description: Forbidden: bot can't initiate conversation with a user\n",
            "2023-05-04 15:01:47,567 (__init__.py:1085 MainThread) ERROR - TeleBot: \"Exception traceback:\n",
            "Traceback (most recent call last):\n",
            "  File \"/usr/local/lib/python3.10/dist-packages/telebot/__init__.py\", line 1074, in __threaded_polling\n",
            "    self.worker_pool.raise_exceptions()\n",
            "  File \"/usr/local/lib/python3.10/dist-packages/telebot/util.py\", line 147, in raise_exceptions\n",
            "    raise self.exception_info\n",
            "  File \"/usr/local/lib/python3.10/dist-packages/telebot/util.py\", line 90, in run\n",
            "    task(*args, **kwargs)\n",
            "  File \"/usr/local/lib/python3.10/dist-packages/telebot/__init__.py\", line 6720, in _run_middlewares_and_handler\n",
            "    result = handler['function'](message)\n",
            "  File \"<ipython-input-8-7f795ddbf42d>\", line 6, in url\n",
            "    bot.send_message(message.from_user.id, \"Привет , меня зовут Wiki! Если ты хочешь перейти в Русский Викисловарь, нажми на кнопку  ниже. Или введи любое слово чтобы узнать что это такое из энциклопедии! \", reply_markup = markup)\n",
            "  File \"/usr/local/lib/python3.10/dist-packages/telebot/__init__.py\", line 1549, in send_message\n",
            "    apihelper.send_message(\n",
            "  File \"/usr/local/lib/python3.10/dist-packages/telebot/apihelper.py\", line 264, in send_message\n",
            "    return _make_request(token, method_url, params=payload, method='post')\n",
            "  File \"/usr/local/lib/python3.10/dist-packages/telebot/apihelper.py\", line 162, in _make_request\n",
            "    json_result = _check_result(method_name, result)\n",
            "  File \"/usr/local/lib/python3.10/dist-packages/telebot/apihelper.py\", line 189, in _check_result\n",
            "    raise ApiTelegramException(method_name, result, result_json)\n",
            "telebot.apihelper.ApiTelegramException: A request to the Telegram API was unsuccessful. Error code: 403. Description: Forbidden: bot can't initiate conversation with a user\n",
            "\"\n",
            "ERROR:TeleBot:Exception traceback:\n",
            "Traceback (most recent call last):\n",
            "  File \"/usr/local/lib/python3.10/dist-packages/telebot/__init__.py\", line 1074, in __threaded_polling\n",
            "    self.worker_pool.raise_exceptions()\n",
            "  File \"/usr/local/lib/python3.10/dist-packages/telebot/util.py\", line 147, in raise_exceptions\n",
            "    raise self.exception_info\n",
            "  File \"/usr/local/lib/python3.10/dist-packages/telebot/util.py\", line 90, in run\n",
            "    task(*args, **kwargs)\n",
            "  File \"/usr/local/lib/python3.10/dist-packages/telebot/__init__.py\", line 6720, in _run_middlewares_and_handler\n",
            "    result = handler['function'](message)\n",
            "  File \"<ipython-input-8-7f795ddbf42d>\", line 6, in url\n",
            "    bot.send_message(message.from_user.id, \"Привет , меня зовут Wiki! Если ты хочешь перейти в Русский Викисловарь, нажми на кнопку  ниже. Или введи любое слово чтобы узнать что это такое из энциклопедии! \", reply_markup = markup)\n",
            "  File \"/usr/local/lib/python3.10/dist-packages/telebot/__init__.py\", line 1549, in send_message\n",
            "    apihelper.send_message(\n",
            "  File \"/usr/local/lib/python3.10/dist-packages/telebot/apihelper.py\", line 264, in send_message\n",
            "    return _make_request(token, method_url, params=payload, method='post')\n",
            "  File \"/usr/local/lib/python3.10/dist-packages/telebot/apihelper.py\", line 162, in _make_request\n",
            "    json_result = _check_result(method_name, result)\n",
            "  File \"/usr/local/lib/python3.10/dist-packages/telebot/apihelper.py\", line 189, in _check_result\n",
            "    raise ApiTelegramException(method_name, result, result_json)\n",
            "telebot.apihelper.ApiTelegramException: A request to the Telegram API was unsuccessful. Error code: 403. Description: Forbidden: bot can't initiate conversation with a user\n",
            "\n",
            "2023-05-04 15:01:58,127 (__init__.py:1083 MainThread) ERROR - TeleBot: \"Threaded polling exception: A request to the Telegram API was unsuccessful. Error code: 403. Description: Forbidden: bot can't initiate conversation with a user\"\n",
            "ERROR:TeleBot:Threaded polling exception: A request to the Telegram API was unsuccessful. Error code: 403. Description: Forbidden: bot can't initiate conversation with a user\n",
            "2023-05-04 15:01:58,130 (__init__.py:1085 MainThread) ERROR - TeleBot: \"Exception traceback:\n",
            "Traceback (most recent call last):\n",
            "  File \"/usr/local/lib/python3.10/dist-packages/telebot/__init__.py\", line 1074, in __threaded_polling\n",
            "    self.worker_pool.raise_exceptions()\n",
            "  File \"/usr/local/lib/python3.10/dist-packages/telebot/util.py\", line 147, in raise_exceptions\n",
            "    raise self.exception_info\n",
            "  File \"/usr/local/lib/python3.10/dist-packages/telebot/util.py\", line 90, in run\n",
            "    task(*args, **kwargs)\n",
            "  File \"/usr/local/lib/python3.10/dist-packages/telebot/__init__.py\", line 6720, in _run_middlewares_and_handler\n",
            "    result = handler['function'](message)\n",
            "  File \"<ipython-input-8-7f795ddbf42d>\", line 6, in url\n",
            "    bot.send_message(message.from_user.id, \"Привет , меня зовут Wiki! Если ты хочешь перейти в Русский Викисловарь, нажми на кнопку  ниже. Или введи любое слово чтобы узнать что это такое из энциклопедии! \", reply_markup = markup)\n",
            "  File \"/usr/local/lib/python3.10/dist-packages/telebot/__init__.py\", line 1549, in send_message\n",
            "    apihelper.send_message(\n",
            "  File \"/usr/local/lib/python3.10/dist-packages/telebot/apihelper.py\", line 264, in send_message\n",
            "    return _make_request(token, method_url, params=payload, method='post')\n",
            "  File \"/usr/local/lib/python3.10/dist-packages/telebot/apihelper.py\", line 162, in _make_request\n",
            "    json_result = _check_result(method_name, result)\n",
            "  File \"/usr/local/lib/python3.10/dist-packages/telebot/apihelper.py\", line 189, in _check_result\n",
            "    raise ApiTelegramException(method_name, result, result_json)\n",
            "telebot.apihelper.ApiTelegramException: A request to the Telegram API was unsuccessful. Error code: 403. Description: Forbidden: bot can't initiate conversation with a user\n",
            "\"\n",
            "ERROR:TeleBot:Exception traceback:\n",
            "Traceback (most recent call last):\n",
            "  File \"/usr/local/lib/python3.10/dist-packages/telebot/__init__.py\", line 1074, in __threaded_polling\n",
            "    self.worker_pool.raise_exceptions()\n",
            "  File \"/usr/local/lib/python3.10/dist-packages/telebot/util.py\", line 147, in raise_exceptions\n",
            "    raise self.exception_info\n",
            "  File \"/usr/local/lib/python3.10/dist-packages/telebot/util.py\", line 90, in run\n",
            "    task(*args, **kwargs)\n",
            "  File \"/usr/local/lib/python3.10/dist-packages/telebot/__init__.py\", line 6720, in _run_middlewares_and_handler\n",
            "    result = handler['function'](message)\n",
            "  File \"<ipython-input-8-7f795ddbf42d>\", line 6, in url\n",
            "    bot.send_message(message.from_user.id, \"Привет , меня зовут Wiki! Если ты хочешь перейти в Русский Викисловарь, нажми на кнопку  ниже. Или введи любое слово чтобы узнать что это такое из энциклопедии! \", reply_markup = markup)\n",
            "  File \"/usr/local/lib/python3.10/dist-packages/telebot/__init__.py\", line 1549, in send_message\n",
            "    apihelper.send_message(\n",
            "  File \"/usr/local/lib/python3.10/dist-packages/telebot/apihelper.py\", line 264, in send_message\n",
            "    return _make_request(token, method_url, params=payload, method='post')\n",
            "  File \"/usr/local/lib/python3.10/dist-packages/telebot/apihelper.py\", line 162, in _make_request\n",
            "    json_result = _check_result(method_name, result)\n",
            "  File \"/usr/local/lib/python3.10/dist-packages/telebot/apihelper.py\", line 189, in _check_result\n",
            "    raise ApiTelegramException(method_name, result, result_json)\n",
            "telebot.apihelper.ApiTelegramException: A request to the Telegram API was unsuccessful. Error code: 403. Description: Forbidden: bot can't initiate conversation with a user\n",
            "\n",
            "2023-05-04 15:02:03,813 (__init__.py:1083 MainThread) ERROR - TeleBot: \"Threaded polling exception: A request to the Telegram API was unsuccessful. Error code: 403. Description: Forbidden: bot can't initiate conversation with a user\"\n",
            "ERROR:TeleBot:Threaded polling exception: A request to the Telegram API was unsuccessful. Error code: 403. Description: Forbidden: bot can't initiate conversation with a user\n",
            "2023-05-04 15:02:03,815 (__init__.py:1085 MainThread) ERROR - TeleBot: \"Exception traceback:\n",
            "Traceback (most recent call last):\n",
            "  File \"/usr/local/lib/python3.10/dist-packages/telebot/__init__.py\", line 1074, in __threaded_polling\n",
            "    self.worker_pool.raise_exceptions()\n",
            "  File \"/usr/local/lib/python3.10/dist-packages/telebot/util.py\", line 147, in raise_exceptions\n",
            "    raise self.exception_info\n",
            "  File \"/usr/local/lib/python3.10/dist-packages/telebot/util.py\", line 90, in run\n",
            "    task(*args, **kwargs)\n",
            "  File \"/usr/local/lib/python3.10/dist-packages/telebot/__init__.py\", line 6720, in _run_middlewares_and_handler\n",
            "    result = handler['function'](message)\n",
            "  File \"<ipython-input-8-7f795ddbf42d>\", line 6, in url\n",
            "    bot.send_message(message.from_user.id, \"Привет , меня зовут Wiki! Если ты хочешь перейти в Русский Викисловарь, нажми на кнопку  ниже. Или введи любое слово чтобы узнать что это такое из энциклопедии! \", reply_markup = markup)\n",
            "  File \"/usr/local/lib/python3.10/dist-packages/telebot/__init__.py\", line 1549, in send_message\n",
            "    apihelper.send_message(\n",
            "  File \"/usr/local/lib/python3.10/dist-packages/telebot/apihelper.py\", line 264, in send_message\n",
            "    return _make_request(token, method_url, params=payload, method='post')\n",
            "  File \"/usr/local/lib/python3.10/dist-packages/telebot/apihelper.py\", line 162, in _make_request\n",
            "    json_result = _check_result(method_name, result)\n",
            "  File \"/usr/local/lib/python3.10/dist-packages/telebot/apihelper.py\", line 189, in _check_result\n",
            "    raise ApiTelegramException(method_name, result, result_json)\n",
            "telebot.apihelper.ApiTelegramException: A request to the Telegram API was unsuccessful. Error code: 403. Description: Forbidden: bot can't initiate conversation with a user\n",
            "\"\n",
            "ERROR:TeleBot:Exception traceback:\n",
            "Traceback (most recent call last):\n",
            "  File \"/usr/local/lib/python3.10/dist-packages/telebot/__init__.py\", line 1074, in __threaded_polling\n",
            "    self.worker_pool.raise_exceptions()\n",
            "  File \"/usr/local/lib/python3.10/dist-packages/telebot/util.py\", line 147, in raise_exceptions\n",
            "    raise self.exception_info\n",
            "  File \"/usr/local/lib/python3.10/dist-packages/telebot/util.py\", line 90, in run\n",
            "    task(*args, **kwargs)\n",
            "  File \"/usr/local/lib/python3.10/dist-packages/telebot/__init__.py\", line 6720, in _run_middlewares_and_handler\n",
            "    result = handler['function'](message)\n",
            "  File \"<ipython-input-8-7f795ddbf42d>\", line 6, in url\n",
            "    bot.send_message(message.from_user.id, \"Привет , меня зовут Wiki! Если ты хочешь перейти в Русский Викисловарь, нажми на кнопку  ниже. Или введи любое слово чтобы узнать что это такое из энциклопедии! \", reply_markup = markup)\n",
            "  File \"/usr/local/lib/python3.10/dist-packages/telebot/__init__.py\", line 1549, in send_message\n",
            "    apihelper.send_message(\n",
            "  File \"/usr/local/lib/python3.10/dist-packages/telebot/apihelper.py\", line 264, in send_message\n",
            "    return _make_request(token, method_url, params=payload, method='post')\n",
            "  File \"/usr/local/lib/python3.10/dist-packages/telebot/apihelper.py\", line 162, in _make_request\n",
            "    json_result = _check_result(method_name, result)\n",
            "  File \"/usr/local/lib/python3.10/dist-packages/telebot/apihelper.py\", line 189, in _check_result\n",
            "    raise ApiTelegramException(method_name, result, result_json)\n",
            "telebot.apihelper.ApiTelegramException: A request to the Telegram API was unsuccessful. Error code: 403. Description: Forbidden: bot can't initiate conversation with a user\n",
            "\n",
            "2023-05-04 15:02:13,160 (__init__.py:1083 MainThread) ERROR - TeleBot: \"Threaded polling exception: A request to the Telegram API was unsuccessful. Error code: 403. Description: Forbidden: bot can't initiate conversation with a user\"\n",
            "ERROR:TeleBot:Threaded polling exception: A request to the Telegram API was unsuccessful. Error code: 403. Description: Forbidden: bot can't initiate conversation with a user\n",
            "2023-05-04 15:02:13,162 (__init__.py:1085 MainThread) ERROR - TeleBot: \"Exception traceback:\n",
            "Traceback (most recent call last):\n",
            "  File \"/usr/local/lib/python3.10/dist-packages/telebot/__init__.py\", line 1074, in __threaded_polling\n",
            "    self.worker_pool.raise_exceptions()\n",
            "  File \"/usr/local/lib/python3.10/dist-packages/telebot/util.py\", line 147, in raise_exceptions\n",
            "    raise self.exception_info\n",
            "  File \"/usr/local/lib/python3.10/dist-packages/telebot/util.py\", line 90, in run\n",
            "    task(*args, **kwargs)\n",
            "  File \"/usr/local/lib/python3.10/dist-packages/telebot/__init__.py\", line 6720, in _run_middlewares_and_handler\n",
            "    result = handler['function'](message)\n",
            "  File \"<ipython-input-8-7f795ddbf42d>\", line 6, in url\n",
            "    bot.send_message(message.from_user.id, \"Привет , меня зовут Wiki! Если ты хочешь перейти в Русский Викисловарь, нажми на кнопку  ниже. Или введи любое слово чтобы узнать что это такое из энциклопедии! \", reply_markup = markup)\n",
            "  File \"/usr/local/lib/python3.10/dist-packages/telebot/__init__.py\", line 1549, in send_message\n",
            "    apihelper.send_message(\n",
            "  File \"/usr/local/lib/python3.10/dist-packages/telebot/apihelper.py\", line 264, in send_message\n",
            "    return _make_request(token, method_url, params=payload, method='post')\n",
            "  File \"/usr/local/lib/python3.10/dist-packages/telebot/apihelper.py\", line 162, in _make_request\n",
            "    json_result = _check_result(method_name, result)\n",
            "  File \"/usr/local/lib/python3.10/dist-packages/telebot/apihelper.py\", line 189, in _check_result\n",
            "    raise ApiTelegramException(method_name, result, result_json)\n",
            "telebot.apihelper.ApiTelegramException: A request to the Telegram API was unsuccessful. Error code: 403. Description: Forbidden: bot can't initiate conversation with a user\n",
            "\"\n",
            "ERROR:TeleBot:Exception traceback:\n",
            "Traceback (most recent call last):\n",
            "  File \"/usr/local/lib/python3.10/dist-packages/telebot/__init__.py\", line 1074, in __threaded_polling\n",
            "    self.worker_pool.raise_exceptions()\n",
            "  File \"/usr/local/lib/python3.10/dist-packages/telebot/util.py\", line 147, in raise_exceptions\n",
            "    raise self.exception_info\n",
            "  File \"/usr/local/lib/python3.10/dist-packages/telebot/util.py\", line 90, in run\n",
            "    task(*args, **kwargs)\n",
            "  File \"/usr/local/lib/python3.10/dist-packages/telebot/__init__.py\", line 6720, in _run_middlewares_and_handler\n",
            "    result = handler['function'](message)\n",
            "  File \"<ipython-input-8-7f795ddbf42d>\", line 6, in url\n",
            "    bot.send_message(message.from_user.id, \"Привет , меня зовут Wiki! Если ты хочешь перейти в Русский Викисловарь, нажми на кнопку  ниже. Или введи любое слово чтобы узнать что это такое из энциклопедии! \", reply_markup = markup)\n",
            "  File \"/usr/local/lib/python3.10/dist-packages/telebot/__init__.py\", line 1549, in send_message\n",
            "    apihelper.send_message(\n",
            "  File \"/usr/local/lib/python3.10/dist-packages/telebot/apihelper.py\", line 264, in send_message\n",
            "    return _make_request(token, method_url, params=payload, method='post')\n",
            "  File \"/usr/local/lib/python3.10/dist-packages/telebot/apihelper.py\", line 162, in _make_request\n",
            "    json_result = _check_result(method_name, result)\n",
            "  File \"/usr/local/lib/python3.10/dist-packages/telebot/apihelper.py\", line 189, in _check_result\n",
            "    raise ApiTelegramException(method_name, result, result_json)\n",
            "telebot.apihelper.ApiTelegramException: A request to the Telegram API was unsuccessful. Error code: 403. Description: Forbidden: bot can't initiate conversation with a user\n",
            "\n",
            "2023-05-04 15:02:24,038 (__init__.py:1083 MainThread) ERROR - TeleBot: \"Threaded polling exception: A request to the Telegram API was unsuccessful. Error code: 403. Description: Forbidden: bot can't initiate conversation with a user\"\n",
            "ERROR:TeleBot:Threaded polling exception: A request to the Telegram API was unsuccessful. Error code: 403. Description: Forbidden: bot can't initiate conversation with a user\n",
            "2023-05-04 15:02:24,042 (__init__.py:1085 MainThread) ERROR - TeleBot: \"Exception traceback:\n",
            "Traceback (most recent call last):\n",
            "  File \"/usr/local/lib/python3.10/dist-packages/telebot/__init__.py\", line 1074, in __threaded_polling\n",
            "    self.worker_pool.raise_exceptions()\n",
            "  File \"/usr/local/lib/python3.10/dist-packages/telebot/util.py\", line 147, in raise_exceptions\n",
            "    raise self.exception_info\n",
            "  File \"/usr/local/lib/python3.10/dist-packages/telebot/util.py\", line 90, in run\n",
            "    task(*args, **kwargs)\n",
            "  File \"/usr/local/lib/python3.10/dist-packages/telebot/__init__.py\", line 6720, in _run_middlewares_and_handler\n",
            "    result = handler['function'](message)\n",
            "  File \"<ipython-input-8-7f795ddbf42d>\", line 6, in url\n",
            "    bot.send_message(message.from_user.id, \"Привет , меня зовут Wiki! Если ты хочешь перейти в Русский Викисловарь, нажми на кнопку  ниже. Или введи любое слово чтобы узнать что это такое из энциклопедии! \", reply_markup = markup)\n",
            "  File \"/usr/local/lib/python3.10/dist-packages/telebot/__init__.py\", line 1549, in send_message\n",
            "    apihelper.send_message(\n",
            "  File \"/usr/local/lib/python3.10/dist-packages/telebot/apihelper.py\", line 264, in send_message\n",
            "    return _make_request(token, method_url, params=payload, method='post')\n",
            "  File \"/usr/local/lib/python3.10/dist-packages/telebot/apihelper.py\", line 162, in _make_request\n",
            "    json_result = _check_result(method_name, result)\n",
            "  File \"/usr/local/lib/python3.10/dist-packages/telebot/apihelper.py\", line 189, in _check_result\n",
            "    raise ApiTelegramException(method_name, result, result_json)\n",
            "telebot.apihelper.ApiTelegramException: A request to the Telegram API was unsuccessful. Error code: 403. Description: Forbidden: bot can't initiate conversation with a user\n",
            "\"\n",
            "ERROR:TeleBot:Exception traceback:\n",
            "Traceback (most recent call last):\n",
            "  File \"/usr/local/lib/python3.10/dist-packages/telebot/__init__.py\", line 1074, in __threaded_polling\n",
            "    self.worker_pool.raise_exceptions()\n",
            "  File \"/usr/local/lib/python3.10/dist-packages/telebot/util.py\", line 147, in raise_exceptions\n",
            "    raise self.exception_info\n",
            "  File \"/usr/local/lib/python3.10/dist-packages/telebot/util.py\", line 90, in run\n",
            "    task(*args, **kwargs)\n",
            "  File \"/usr/local/lib/python3.10/dist-packages/telebot/__init__.py\", line 6720, in _run_middlewares_and_handler\n",
            "    result = handler['function'](message)\n",
            "  File \"<ipython-input-8-7f795ddbf42d>\", line 6, in url\n",
            "    bot.send_message(message.from_user.id, \"Привет , меня зовут Wiki! Если ты хочешь перейти в Русский Викисловарь, нажми на кнопку  ниже. Или введи любое слово чтобы узнать что это такое из энциклопедии! \", reply_markup = markup)\n",
            "  File \"/usr/local/lib/python3.10/dist-packages/telebot/__init__.py\", line 1549, in send_message\n",
            "    apihelper.send_message(\n",
            "  File \"/usr/local/lib/python3.10/dist-packages/telebot/apihelper.py\", line 264, in send_message\n",
            "    return _make_request(token, method_url, params=payload, method='post')\n",
            "  File \"/usr/local/lib/python3.10/dist-packages/telebot/apihelper.py\", line 162, in _make_request\n",
            "    json_result = _check_result(method_name, result)\n",
            "  File \"/usr/local/lib/python3.10/dist-packages/telebot/apihelper.py\", line 189, in _check_result\n",
            "    raise ApiTelegramException(method_name, result, result_json)\n",
            "telebot.apihelper.ApiTelegramException: A request to the Telegram API was unsuccessful. Error code: 403. Description: Forbidden: bot can't initiate conversation with a user\n",
            "\n",
            "2023-05-04 15:03:44,268 (__init__.py:1083 MainThread) ERROR - TeleBot: \"Threaded polling exception: A request to the Telegram API was unsuccessful. Error code: 403. Description: Forbidden: bot can't initiate conversation with a user\"\n",
            "ERROR:TeleBot:Threaded polling exception: A request to the Telegram API was unsuccessful. Error code: 403. Description: Forbidden: bot can't initiate conversation with a user\n",
            "2023-05-04 15:03:44,271 (__init__.py:1085 MainThread) ERROR - TeleBot: \"Exception traceback:\n",
            "Traceback (most recent call last):\n",
            "  File \"/usr/local/lib/python3.10/dist-packages/telebot/__init__.py\", line 1074, in __threaded_polling\n",
            "    self.worker_pool.raise_exceptions()\n",
            "  File \"/usr/local/lib/python3.10/dist-packages/telebot/util.py\", line 147, in raise_exceptions\n",
            "    raise self.exception_info\n",
            "  File \"/usr/local/lib/python3.10/dist-packages/telebot/util.py\", line 90, in run\n",
            "    task(*args, **kwargs)\n",
            "  File \"/usr/local/lib/python3.10/dist-packages/telebot/__init__.py\", line 6720, in _run_middlewares_and_handler\n",
            "    result = handler['function'](message)\n",
            "  File \"<ipython-input-8-7f795ddbf42d>\", line 6, in url\n",
            "    bot.send_message(message.from_user.id, \"Привет , меня зовут Wiki! Если ты хочешь перейти в Русский Викисловарь, нажми на кнопку  ниже. Или введи любое слово чтобы узнать что это такое из энциклопедии! \", reply_markup = markup)\n",
            "  File \"/usr/local/lib/python3.10/dist-packages/telebot/__init__.py\", line 1549, in send_message\n",
            "    apihelper.send_message(\n",
            "  File \"/usr/local/lib/python3.10/dist-packages/telebot/apihelper.py\", line 264, in send_message\n",
            "    return _make_request(token, method_url, params=payload, method='post')\n",
            "  File \"/usr/local/lib/python3.10/dist-packages/telebot/apihelper.py\", line 162, in _make_request\n",
            "    json_result = _check_result(method_name, result)\n",
            "  File \"/usr/local/lib/python3.10/dist-packages/telebot/apihelper.py\", line 189, in _check_result\n",
            "    raise ApiTelegramException(method_name, result, result_json)\n",
            "telebot.apihelper.ApiTelegramException: A request to the Telegram API was unsuccessful. Error code: 403. Description: Forbidden: bot can't initiate conversation with a user\n",
            "\"\n",
            "ERROR:TeleBot:Exception traceback:\n",
            "Traceback (most recent call last):\n",
            "  File \"/usr/local/lib/python3.10/dist-packages/telebot/__init__.py\", line 1074, in __threaded_polling\n",
            "    self.worker_pool.raise_exceptions()\n",
            "  File \"/usr/local/lib/python3.10/dist-packages/telebot/util.py\", line 147, in raise_exceptions\n",
            "    raise self.exception_info\n",
            "  File \"/usr/local/lib/python3.10/dist-packages/telebot/util.py\", line 90, in run\n",
            "    task(*args, **kwargs)\n",
            "  File \"/usr/local/lib/python3.10/dist-packages/telebot/__init__.py\", line 6720, in _run_middlewares_and_handler\n",
            "    result = handler['function'](message)\n",
            "  File \"<ipython-input-8-7f795ddbf42d>\", line 6, in url\n",
            "    bot.send_message(message.from_user.id, \"Привет , меня зовут Wiki! Если ты хочешь перейти в Русский Викисловарь, нажми на кнопку  ниже. Или введи любое слово чтобы узнать что это такое из энциклопедии! \", reply_markup = markup)\n",
            "  File \"/usr/local/lib/python3.10/dist-packages/telebot/__init__.py\", line 1549, in send_message\n",
            "    apihelper.send_message(\n",
            "  File \"/usr/local/lib/python3.10/dist-packages/telebot/apihelper.py\", line 264, in send_message\n",
            "    return _make_request(token, method_url, params=payload, method='post')\n",
            "  File \"/usr/local/lib/python3.10/dist-packages/telebot/apihelper.py\", line 162, in _make_request\n",
            "    json_result = _check_result(method_name, result)\n",
            "  File \"/usr/local/lib/python3.10/dist-packages/telebot/apihelper.py\", line 189, in _check_result\n",
            "    raise ApiTelegramException(method_name, result, result_json)\n",
            "telebot.apihelper.ApiTelegramException: A request to the Telegram API was unsuccessful. Error code: 403. Description: Forbidden: bot can't initiate conversation with a user\n",
            "\n",
            "2023-05-04 15:11:23,875 (__init__.py:1083 MainThread) ERROR - TeleBot: \"Threaded polling exception: A request to the Telegram API was unsuccessful. Error code: 403. Description: Forbidden: bot can't initiate conversation with a user\"\n",
            "ERROR:TeleBot:Threaded polling exception: A request to the Telegram API was unsuccessful. Error code: 403. Description: Forbidden: bot can't initiate conversation with a user\n",
            "2023-05-04 15:11:23,878 (__init__.py:1085 MainThread) ERROR - TeleBot: \"Exception traceback:\n",
            "Traceback (most recent call last):\n",
            "  File \"/usr/local/lib/python3.10/dist-packages/telebot/__init__.py\", line 1074, in __threaded_polling\n",
            "    self.worker_pool.raise_exceptions()\n",
            "  File \"/usr/local/lib/python3.10/dist-packages/telebot/util.py\", line 147, in raise_exceptions\n",
            "    raise self.exception_info\n",
            "  File \"/usr/local/lib/python3.10/dist-packages/telebot/util.py\", line 90, in run\n",
            "    task(*args, **kwargs)\n",
            "  File \"/usr/local/lib/python3.10/dist-packages/telebot/__init__.py\", line 6720, in _run_middlewares_and_handler\n",
            "    result = handler['function'](message)\n",
            "  File \"<ipython-input-8-7f795ddbf42d>\", line 6, in url\n",
            "    bot.send_message(message.from_user.id, \"Привет , меня зовут Wiki! Если ты хочешь перейти в Русский Викисловарь, нажми на кнопку  ниже. Или введи любое слово чтобы узнать что это такое из энциклопедии! \", reply_markup = markup)\n",
            "  File \"/usr/local/lib/python3.10/dist-packages/telebot/__init__.py\", line 1549, in send_message\n",
            "    apihelper.send_message(\n",
            "  File \"/usr/local/lib/python3.10/dist-packages/telebot/apihelper.py\", line 264, in send_message\n",
            "    return _make_request(token, method_url, params=payload, method='post')\n",
            "  File \"/usr/local/lib/python3.10/dist-packages/telebot/apihelper.py\", line 162, in _make_request\n",
            "    json_result = _check_result(method_name, result)\n",
            "  File \"/usr/local/lib/python3.10/dist-packages/telebot/apihelper.py\", line 189, in _check_result\n",
            "    raise ApiTelegramException(method_name, result, result_json)\n",
            "telebot.apihelper.ApiTelegramException: A request to the Telegram API was unsuccessful. Error code: 403. Description: Forbidden: bot can't initiate conversation with a user\n",
            "\"\n",
            "ERROR:TeleBot:Exception traceback:\n",
            "Traceback (most recent call last):\n",
            "  File \"/usr/local/lib/python3.10/dist-packages/telebot/__init__.py\", line 1074, in __threaded_polling\n",
            "    self.worker_pool.raise_exceptions()\n",
            "  File \"/usr/local/lib/python3.10/dist-packages/telebot/util.py\", line 147, in raise_exceptions\n",
            "    raise self.exception_info\n",
            "  File \"/usr/local/lib/python3.10/dist-packages/telebot/util.py\", line 90, in run\n",
            "    task(*args, **kwargs)\n",
            "  File \"/usr/local/lib/python3.10/dist-packages/telebot/__init__.py\", line 6720, in _run_middlewares_and_handler\n",
            "    result = handler['function'](message)\n",
            "  File \"<ipython-input-8-7f795ddbf42d>\", line 6, in url\n",
            "    bot.send_message(message.from_user.id, \"Привет , меня зовут Wiki! Если ты хочешь перейти в Русский Викисловарь, нажми на кнопку  ниже. Или введи любое слово чтобы узнать что это такое из энциклопедии! \", reply_markup = markup)\n",
            "  File \"/usr/local/lib/python3.10/dist-packages/telebot/__init__.py\", line 1549, in send_message\n",
            "    apihelper.send_message(\n",
            "  File \"/usr/local/lib/python3.10/dist-packages/telebot/apihelper.py\", line 264, in send_message\n",
            "    return _make_request(token, method_url, params=payload, method='post')\n",
            "  File \"/usr/local/lib/python3.10/dist-packages/telebot/apihelper.py\", line 162, in _make_request\n",
            "    json_result = _check_result(method_name, result)\n",
            "  File \"/usr/local/lib/python3.10/dist-packages/telebot/apihelper.py\", line 189, in _check_result\n",
            "    raise ApiTelegramException(method_name, result, result_json)\n",
            "telebot.apihelper.ApiTelegramException: A request to the Telegram API was unsuccessful. Error code: 403. Description: Forbidden: bot can't initiate conversation with a user\n",
            "\n",
            "2023-05-04 15:15:16,431 (__init__.py:1083 MainThread) ERROR - TeleBot: \"Threaded polling exception: A request to the Telegram API was unsuccessful. Error code: 403. Description: Forbidden: bot can't initiate conversation with a user\"\n",
            "ERROR:TeleBot:Threaded polling exception: A request to the Telegram API was unsuccessful. Error code: 403. Description: Forbidden: bot can't initiate conversation with a user\n",
            "2023-05-04 15:15:16,435 (__init__.py:1085 MainThread) ERROR - TeleBot: \"Exception traceback:\n",
            "Traceback (most recent call last):\n",
            "  File \"/usr/local/lib/python3.10/dist-packages/telebot/__init__.py\", line 1074, in __threaded_polling\n",
            "    self.worker_pool.raise_exceptions()\n",
            "  File \"/usr/local/lib/python3.10/dist-packages/telebot/util.py\", line 147, in raise_exceptions\n",
            "    raise self.exception_info\n",
            "  File \"/usr/local/lib/python3.10/dist-packages/telebot/util.py\", line 90, in run\n",
            "    task(*args, **kwargs)\n",
            "  File \"/usr/local/lib/python3.10/dist-packages/telebot/__init__.py\", line 6720, in _run_middlewares_and_handler\n",
            "    result = handler['function'](message)\n",
            "  File \"<ipython-input-8-7f795ddbf42d>\", line 6, in url\n",
            "    bot.send_message(message.from_user.id, \"Привет , меня зовут Wiki! Если ты хочешь перейти в Русский Викисловарь, нажми на кнопку  ниже. Или введи любое слово чтобы узнать что это такое из энциклопедии! \", reply_markup = markup)\n",
            "  File \"/usr/local/lib/python3.10/dist-packages/telebot/__init__.py\", line 1549, in send_message\n",
            "    apihelper.send_message(\n",
            "  File \"/usr/local/lib/python3.10/dist-packages/telebot/apihelper.py\", line 264, in send_message\n",
            "    return _make_request(token, method_url, params=payload, method='post')\n",
            "  File \"/usr/local/lib/python3.10/dist-packages/telebot/apihelper.py\", line 162, in _make_request\n",
            "    json_result = _check_result(method_name, result)\n",
            "  File \"/usr/local/lib/python3.10/dist-packages/telebot/apihelper.py\", line 189, in _check_result\n",
            "    raise ApiTelegramException(method_name, result, result_json)\n",
            "telebot.apihelper.ApiTelegramException: A request to the Telegram API was unsuccessful. Error code: 403. Description: Forbidden: bot can't initiate conversation with a user\n",
            "\"\n",
            "ERROR:TeleBot:Exception traceback:\n",
            "Traceback (most recent call last):\n",
            "  File \"/usr/local/lib/python3.10/dist-packages/telebot/__init__.py\", line 1074, in __threaded_polling\n",
            "    self.worker_pool.raise_exceptions()\n",
            "  File \"/usr/local/lib/python3.10/dist-packages/telebot/util.py\", line 147, in raise_exceptions\n",
            "    raise self.exception_info\n",
            "  File \"/usr/local/lib/python3.10/dist-packages/telebot/util.py\", line 90, in run\n",
            "    task(*args, **kwargs)\n",
            "  File \"/usr/local/lib/python3.10/dist-packages/telebot/__init__.py\", line 6720, in _run_middlewares_and_handler\n",
            "    result = handler['function'](message)\n",
            "  File \"<ipython-input-8-7f795ddbf42d>\", line 6, in url\n",
            "    bot.send_message(message.from_user.id, \"Привет , меня зовут Wiki! Если ты хочешь перейти в Русский Викисловарь, нажми на кнопку  ниже. Или введи любое слово чтобы узнать что это такое из энциклопедии! \", reply_markup = markup)\n",
            "  File \"/usr/local/lib/python3.10/dist-packages/telebot/__init__.py\", line 1549, in send_message\n",
            "    apihelper.send_message(\n",
            "  File \"/usr/local/lib/python3.10/dist-packages/telebot/apihelper.py\", line 264, in send_message\n",
            "    return _make_request(token, method_url, params=payload, method='post')\n",
            "  File \"/usr/local/lib/python3.10/dist-packages/telebot/apihelper.py\", line 162, in _make_request\n",
            "    json_result = _check_result(method_name, result)\n",
            "  File \"/usr/local/lib/python3.10/dist-packages/telebot/apihelper.py\", line 189, in _check_result\n",
            "    raise ApiTelegramException(method_name, result, result_json)\n",
            "telebot.apihelper.ApiTelegramException: A request to the Telegram API was unsuccessful. Error code: 403. Description: Forbidden: bot can't initiate conversation with a user\n",
            "\n",
            "2023-05-04 15:16:03,731 (__init__.py:1083 MainThread) ERROR - TeleBot: \"Threaded polling exception: A request to the Telegram API was unsuccessful. Error code: 403. Description: Forbidden: bot can't initiate conversation with a user\"\n",
            "ERROR:TeleBot:Threaded polling exception: A request to the Telegram API was unsuccessful. Error code: 403. Description: Forbidden: bot can't initiate conversation with a user\n",
            "2023-05-04 15:16:03,734 (__init__.py:1085 MainThread) ERROR - TeleBot: \"Exception traceback:\n",
            "Traceback (most recent call last):\n",
            "  File \"/usr/local/lib/python3.10/dist-packages/telebot/__init__.py\", line 1074, in __threaded_polling\n",
            "    self.worker_pool.raise_exceptions()\n",
            "  File \"/usr/local/lib/python3.10/dist-packages/telebot/util.py\", line 147, in raise_exceptions\n",
            "    raise self.exception_info\n",
            "  File \"/usr/local/lib/python3.10/dist-packages/telebot/util.py\", line 90, in run\n",
            "    task(*args, **kwargs)\n",
            "  File \"/usr/local/lib/python3.10/dist-packages/telebot/__init__.py\", line 6720, in _run_middlewares_and_handler\n",
            "    result = handler['function'](message)\n",
            "  File \"<ipython-input-8-7f795ddbf42d>\", line 6, in url\n",
            "    bot.send_message(message.from_user.id, \"Привет , меня зовут Wiki! Если ты хочешь перейти в Русский Викисловарь, нажми на кнопку  ниже. Или введи любое слово чтобы узнать что это такое из энциклопедии! \", reply_markup = markup)\n",
            "  File \"/usr/local/lib/python3.10/dist-packages/telebot/__init__.py\", line 1549, in send_message\n",
            "    apihelper.send_message(\n",
            "  File \"/usr/local/lib/python3.10/dist-packages/telebot/apihelper.py\", line 264, in send_message\n",
            "    return _make_request(token, method_url, params=payload, method='post')\n",
            "  File \"/usr/local/lib/python3.10/dist-packages/telebot/apihelper.py\", line 162, in _make_request\n",
            "    json_result = _check_result(method_name, result)\n",
            "  File \"/usr/local/lib/python3.10/dist-packages/telebot/apihelper.py\", line 189, in _check_result\n",
            "    raise ApiTelegramException(method_name, result, result_json)\n",
            "telebot.apihelper.ApiTelegramException: A request to the Telegram API was unsuccessful. Error code: 403. Description: Forbidden: bot can't initiate conversation with a user\n",
            "\"\n",
            "ERROR:TeleBot:Exception traceback:\n",
            "Traceback (most recent call last):\n",
            "  File \"/usr/local/lib/python3.10/dist-packages/telebot/__init__.py\", line 1074, in __threaded_polling\n",
            "    self.worker_pool.raise_exceptions()\n",
            "  File \"/usr/local/lib/python3.10/dist-packages/telebot/util.py\", line 147, in raise_exceptions\n",
            "    raise self.exception_info\n",
            "  File \"/usr/local/lib/python3.10/dist-packages/telebot/util.py\", line 90, in run\n",
            "    task(*args, **kwargs)\n",
            "  File \"/usr/local/lib/python3.10/dist-packages/telebot/__init__.py\", line 6720, in _run_middlewares_and_handler\n",
            "    result = handler['function'](message)\n",
            "  File \"<ipython-input-8-7f795ddbf42d>\", line 6, in url\n",
            "    bot.send_message(message.from_user.id, \"Привет , меня зовут Wiki! Если ты хочешь перейти в Русский Викисловарь, нажми на кнопку  ниже. Или введи любое слово чтобы узнать что это такое из энциклопедии! \", reply_markup = markup)\n",
            "  File \"/usr/local/lib/python3.10/dist-packages/telebot/__init__.py\", line 1549, in send_message\n",
            "    apihelper.send_message(\n",
            "  File \"/usr/local/lib/python3.10/dist-packages/telebot/apihelper.py\", line 264, in send_message\n",
            "    return _make_request(token, method_url, params=payload, method='post')\n",
            "  File \"/usr/local/lib/python3.10/dist-packages/telebot/apihelper.py\", line 162, in _make_request\n",
            "    json_result = _check_result(method_name, result)\n",
            "  File \"/usr/local/lib/python3.10/dist-packages/telebot/apihelper.py\", line 189, in _check_result\n",
            "    raise ApiTelegramException(method_name, result, result_json)\n",
            "telebot.apihelper.ApiTelegramException: A request to the Telegram API was unsuccessful. Error code: 403. Description: Forbidden: bot can't initiate conversation with a user\n",
            "\n",
            "2023-05-04 15:16:31,435 (__init__.py:1083 MainThread) ERROR - TeleBot: \"Threaded polling exception: A request to the Telegram API was unsuccessful. Error code: 403. Description: Forbidden: bot can't initiate conversation with a user\"\n",
            "ERROR:TeleBot:Threaded polling exception: A request to the Telegram API was unsuccessful. Error code: 403. Description: Forbidden: bot can't initiate conversation with a user\n",
            "2023-05-04 15:16:31,438 (__init__.py:1085 MainThread) ERROR - TeleBot: \"Exception traceback:\n",
            "Traceback (most recent call last):\n",
            "  File \"/usr/local/lib/python3.10/dist-packages/telebot/__init__.py\", line 1074, in __threaded_polling\n",
            "    self.worker_pool.raise_exceptions()\n",
            "  File \"/usr/local/lib/python3.10/dist-packages/telebot/util.py\", line 147, in raise_exceptions\n",
            "    raise self.exception_info\n",
            "  File \"/usr/local/lib/python3.10/dist-packages/telebot/util.py\", line 90, in run\n",
            "    task(*args, **kwargs)\n",
            "  File \"/usr/local/lib/python3.10/dist-packages/telebot/__init__.py\", line 6720, in _run_middlewares_and_handler\n",
            "    result = handler['function'](message)\n",
            "  File \"<ipython-input-8-7f795ddbf42d>\", line 6, in url\n",
            "    bot.send_message(message.from_user.id, \"Привет , меня зовут Wiki! Если ты хочешь перейти в Русский Викисловарь, нажми на кнопку  ниже. Или введи любое слово чтобы узнать что это такое из энциклопедии! \", reply_markup = markup)\n",
            "  File \"/usr/local/lib/python3.10/dist-packages/telebot/__init__.py\", line 1549, in send_message\n",
            "    apihelper.send_message(\n",
            "  File \"/usr/local/lib/python3.10/dist-packages/telebot/apihelper.py\", line 264, in send_message\n",
            "    return _make_request(token, method_url, params=payload, method='post')\n",
            "  File \"/usr/local/lib/python3.10/dist-packages/telebot/apihelper.py\", line 162, in _make_request\n",
            "    json_result = _check_result(method_name, result)\n",
            "  File \"/usr/local/lib/python3.10/dist-packages/telebot/apihelper.py\", line 189, in _check_result\n",
            "    raise ApiTelegramException(method_name, result, result_json)\n",
            "telebot.apihelper.ApiTelegramException: A request to the Telegram API was unsuccessful. Error code: 403. Description: Forbidden: bot can't initiate conversation with a user\n",
            "\"\n",
            "ERROR:TeleBot:Exception traceback:\n",
            "Traceback (most recent call last):\n",
            "  File \"/usr/local/lib/python3.10/dist-packages/telebot/__init__.py\", line 1074, in __threaded_polling\n",
            "    self.worker_pool.raise_exceptions()\n",
            "  File \"/usr/local/lib/python3.10/dist-packages/telebot/util.py\", line 147, in raise_exceptions\n",
            "    raise self.exception_info\n",
            "  File \"/usr/local/lib/python3.10/dist-packages/telebot/util.py\", line 90, in run\n",
            "    task(*args, **kwargs)\n",
            "  File \"/usr/local/lib/python3.10/dist-packages/telebot/__init__.py\", line 6720, in _run_middlewares_and_handler\n",
            "    result = handler['function'](message)\n",
            "  File \"<ipython-input-8-7f795ddbf42d>\", line 6, in url\n",
            "    bot.send_message(message.from_user.id, \"Привет , меня зовут Wiki! Если ты хочешь перейти в Русский Викисловарь, нажми на кнопку  ниже. Или введи любое слово чтобы узнать что это такое из энциклопедии! \", reply_markup = markup)\n",
            "  File \"/usr/local/lib/python3.10/dist-packages/telebot/__init__.py\", line 1549, in send_message\n",
            "    apihelper.send_message(\n",
            "  File \"/usr/local/lib/python3.10/dist-packages/telebot/apihelper.py\", line 264, in send_message\n",
            "    return _make_request(token, method_url, params=payload, method='post')\n",
            "  File \"/usr/local/lib/python3.10/dist-packages/telebot/apihelper.py\", line 162, in _make_request\n",
            "    json_result = _check_result(method_name, result)\n",
            "  File \"/usr/local/lib/python3.10/dist-packages/telebot/apihelper.py\", line 189, in _check_result\n",
            "    raise ApiTelegramException(method_name, result, result_json)\n",
            "telebot.apihelper.ApiTelegramException: A request to the Telegram API was unsuccessful. Error code: 403. Description: Forbidden: bot can't initiate conversation with a user\n",
            "\n",
            "2023-05-04 15:17:10,447 (__init__.py:1083 MainThread) ERROR - TeleBot: \"Threaded polling exception: A request to the Telegram API was unsuccessful. Error code: 403. Description: Forbidden: bot can't initiate conversation with a user\"\n",
            "ERROR:TeleBot:Threaded polling exception: A request to the Telegram API was unsuccessful. Error code: 403. Description: Forbidden: bot can't initiate conversation with a user\n",
            "2023-05-04 15:17:10,452 (__init__.py:1085 MainThread) ERROR - TeleBot: \"Exception traceback:\n",
            "Traceback (most recent call last):\n",
            "  File \"/usr/local/lib/python3.10/dist-packages/telebot/__init__.py\", line 1074, in __threaded_polling\n",
            "    self.worker_pool.raise_exceptions()\n",
            "  File \"/usr/local/lib/python3.10/dist-packages/telebot/util.py\", line 147, in raise_exceptions\n",
            "    raise self.exception_info\n",
            "  File \"/usr/local/lib/python3.10/dist-packages/telebot/util.py\", line 90, in run\n",
            "    task(*args, **kwargs)\n",
            "  File \"/usr/local/lib/python3.10/dist-packages/telebot/__init__.py\", line 6720, in _run_middlewares_and_handler\n",
            "    result = handler['function'](message)\n",
            "  File \"<ipython-input-8-7f795ddbf42d>\", line 6, in url\n",
            "    bot.send_message(message.from_user.id, \"Привет , меня зовут Wiki! Если ты хочешь перейти в Русский Викисловарь, нажми на кнопку  ниже. Или введи любое слово чтобы узнать что это такое из энциклопедии! \", reply_markup = markup)\n",
            "  File \"/usr/local/lib/python3.10/dist-packages/telebot/__init__.py\", line 1549, in send_message\n",
            "    apihelper.send_message(\n",
            "  File \"/usr/local/lib/python3.10/dist-packages/telebot/apihelper.py\", line 264, in send_message\n",
            "    return _make_request(token, method_url, params=payload, method='post')\n",
            "  File \"/usr/local/lib/python3.10/dist-packages/telebot/apihelper.py\", line 162, in _make_request\n",
            "    json_result = _check_result(method_name, result)\n",
            "  File \"/usr/local/lib/python3.10/dist-packages/telebot/apihelper.py\", line 189, in _check_result\n",
            "    raise ApiTelegramException(method_name, result, result_json)\n",
            "telebot.apihelper.ApiTelegramException: A request to the Telegram API was unsuccessful. Error code: 403. Description: Forbidden: bot can't initiate conversation with a user\n",
            "\"\n",
            "ERROR:TeleBot:Exception traceback:\n",
            "Traceback (most recent call last):\n",
            "  File \"/usr/local/lib/python3.10/dist-packages/telebot/__init__.py\", line 1074, in __threaded_polling\n",
            "    self.worker_pool.raise_exceptions()\n",
            "  File \"/usr/local/lib/python3.10/dist-packages/telebot/util.py\", line 147, in raise_exceptions\n",
            "    raise self.exception_info\n",
            "  File \"/usr/local/lib/python3.10/dist-packages/telebot/util.py\", line 90, in run\n",
            "    task(*args, **kwargs)\n",
            "  File \"/usr/local/lib/python3.10/dist-packages/telebot/__init__.py\", line 6720, in _run_middlewares_and_handler\n",
            "    result = handler['function'](message)\n",
            "  File \"<ipython-input-8-7f795ddbf42d>\", line 6, in url\n",
            "    bot.send_message(message.from_user.id, \"Привет , меня зовут Wiki! Если ты хочешь перейти в Русский Викисловарь, нажми на кнопку  ниже. Или введи любое слово чтобы узнать что это такое из энциклопедии! \", reply_markup = markup)\n",
            "  File \"/usr/local/lib/python3.10/dist-packages/telebot/__init__.py\", line 1549, in send_message\n",
            "    apihelper.send_message(\n",
            "  File \"/usr/local/lib/python3.10/dist-packages/telebot/apihelper.py\", line 264, in send_message\n",
            "    return _make_request(token, method_url, params=payload, method='post')\n",
            "  File \"/usr/local/lib/python3.10/dist-packages/telebot/apihelper.py\", line 162, in _make_request\n",
            "    json_result = _check_result(method_name, result)\n",
            "  File \"/usr/local/lib/python3.10/dist-packages/telebot/apihelper.py\", line 189, in _check_result\n",
            "    raise ApiTelegramException(method_name, result, result_json)\n",
            "telebot.apihelper.ApiTelegramException: A request to the Telegram API was unsuccessful. Error code: 403. Description: Forbidden: bot can't initiate conversation with a user\n",
            "\n",
            "2023-05-04 15:18:57,190 (__init__.py:1083 MainThread) ERROR - TeleBot: \"Threaded polling exception: A request to the Telegram API was unsuccessful. Error code: 403. Description: Forbidden: bot can't send messages to bots\"\n",
            "ERROR:TeleBot:Threaded polling exception: A request to the Telegram API was unsuccessful. Error code: 403. Description: Forbidden: bot can't send messages to bots\n",
            "2023-05-04 15:18:57,193 (__init__.py:1085 MainThread) ERROR - TeleBot: \"Exception traceback:\n",
            "Traceback (most recent call last):\n",
            "  File \"/usr/local/lib/python3.10/dist-packages/telebot/__init__.py\", line 1074, in __threaded_polling\n",
            "    self.worker_pool.raise_exceptions()\n",
            "  File \"/usr/local/lib/python3.10/dist-packages/telebot/util.py\", line 147, in raise_exceptions\n",
            "    raise self.exception_info\n",
            "  File \"/usr/local/lib/python3.10/dist-packages/telebot/util.py\", line 90, in run\n",
            "    task(*args, **kwargs)\n",
            "  File \"/usr/local/lib/python3.10/dist-packages/telebot/__init__.py\", line 6720, in _run_middlewares_and_handler\n",
            "    result = handler['function'](message)\n",
            "  File \"<ipython-input-8-7f795ddbf42d>\", line 6, in url\n",
            "    bot.send_message(message.from_user.id, \"Привет , меня зовут Wiki! Если ты хочешь перейти в Русский Викисловарь, нажми на кнопку  ниже. Или введи любое слово чтобы узнать что это такое из энциклопедии! \", reply_markup = markup)\n",
            "  File \"/usr/local/lib/python3.10/dist-packages/telebot/__init__.py\", line 1549, in send_message\n",
            "    apihelper.send_message(\n",
            "  File \"/usr/local/lib/python3.10/dist-packages/telebot/apihelper.py\", line 264, in send_message\n",
            "    return _make_request(token, method_url, params=payload, method='post')\n",
            "  File \"/usr/local/lib/python3.10/dist-packages/telebot/apihelper.py\", line 162, in _make_request\n",
            "    json_result = _check_result(method_name, result)\n",
            "  File \"/usr/local/lib/python3.10/dist-packages/telebot/apihelper.py\", line 189, in _check_result\n",
            "    raise ApiTelegramException(method_name, result, result_json)\n",
            "telebot.apihelper.ApiTelegramException: A request to the Telegram API was unsuccessful. Error code: 403. Description: Forbidden: bot can't send messages to bots\n",
            "\"\n",
            "ERROR:TeleBot:Exception traceback:\n",
            "Traceback (most recent call last):\n",
            "  File \"/usr/local/lib/python3.10/dist-packages/telebot/__init__.py\", line 1074, in __threaded_polling\n",
            "    self.worker_pool.raise_exceptions()\n",
            "  File \"/usr/local/lib/python3.10/dist-packages/telebot/util.py\", line 147, in raise_exceptions\n",
            "    raise self.exception_info\n",
            "  File \"/usr/local/lib/python3.10/dist-packages/telebot/util.py\", line 90, in run\n",
            "    task(*args, **kwargs)\n",
            "  File \"/usr/local/lib/python3.10/dist-packages/telebot/__init__.py\", line 6720, in _run_middlewares_and_handler\n",
            "    result = handler['function'](message)\n",
            "  File \"<ipython-input-8-7f795ddbf42d>\", line 6, in url\n",
            "    bot.send_message(message.from_user.id, \"Привет , меня зовут Wiki! Если ты хочешь перейти в Русский Викисловарь, нажми на кнопку  ниже. Или введи любое слово чтобы узнать что это такое из энциклопедии! \", reply_markup = markup)\n",
            "  File \"/usr/local/lib/python3.10/dist-packages/telebot/__init__.py\", line 1549, in send_message\n",
            "    apihelper.send_message(\n",
            "  File \"/usr/local/lib/python3.10/dist-packages/telebot/apihelper.py\", line 264, in send_message\n",
            "    return _make_request(token, method_url, params=payload, method='post')\n",
            "  File \"/usr/local/lib/python3.10/dist-packages/telebot/apihelper.py\", line 162, in _make_request\n",
            "    json_result = _check_result(method_name, result)\n",
            "  File \"/usr/local/lib/python3.10/dist-packages/telebot/apihelper.py\", line 189, in _check_result\n",
            "    raise ApiTelegramException(method_name, result, result_json)\n",
            "telebot.apihelper.ApiTelegramException: A request to the Telegram API was unsuccessful. Error code: 403. Description: Forbidden: bot can't send messages to bots\n",
            "\n",
            "2023-05-04 15:31:20,820 (__init__.py:1083 MainThread) ERROR - TeleBot: \"Threaded polling exception: A request to the Telegram API was unsuccessful. Error code: 403. Description: Forbidden: bot can't initiate conversation with a user\"\n",
            "ERROR:TeleBot:Threaded polling exception: A request to the Telegram API was unsuccessful. Error code: 403. Description: Forbidden: bot can't initiate conversation with a user\n",
            "2023-05-04 15:31:20,824 (__init__.py:1085 MainThread) ERROR - TeleBot: \"Exception traceback:\n",
            "Traceback (most recent call last):\n",
            "  File \"/usr/local/lib/python3.10/dist-packages/telebot/__init__.py\", line 1074, in __threaded_polling\n",
            "    self.worker_pool.raise_exceptions()\n",
            "  File \"/usr/local/lib/python3.10/dist-packages/telebot/util.py\", line 147, in raise_exceptions\n",
            "    raise self.exception_info\n",
            "  File \"/usr/local/lib/python3.10/dist-packages/telebot/util.py\", line 90, in run\n",
            "    task(*args, **kwargs)\n",
            "  File \"/usr/local/lib/python3.10/dist-packages/telebot/__init__.py\", line 6720, in _run_middlewares_and_handler\n",
            "    result = handler['function'](message)\n",
            "  File \"<ipython-input-8-7f795ddbf42d>\", line 6, in url\n",
            "    bot.send_message(message.from_user.id, \"Привет , меня зовут Wiki! Если ты хочешь перейти в Русский Викисловарь, нажми на кнопку  ниже. Или введи любое слово чтобы узнать что это такое из энциклопедии! \", reply_markup = markup)\n",
            "  File \"/usr/local/lib/python3.10/dist-packages/telebot/__init__.py\", line 1549, in send_message\n",
            "    apihelper.send_message(\n",
            "  File \"/usr/local/lib/python3.10/dist-packages/telebot/apihelper.py\", line 264, in send_message\n",
            "    return _make_request(token, method_url, params=payload, method='post')\n",
            "  File \"/usr/local/lib/python3.10/dist-packages/telebot/apihelper.py\", line 162, in _make_request\n",
            "    json_result = _check_result(method_name, result)\n",
            "  File \"/usr/local/lib/python3.10/dist-packages/telebot/apihelper.py\", line 189, in _check_result\n",
            "    raise ApiTelegramException(method_name, result, result_json)\n",
            "telebot.apihelper.ApiTelegramException: A request to the Telegram API was unsuccessful. Error code: 403. Description: Forbidden: bot can't initiate conversation with a user\n",
            "\"\n",
            "ERROR:TeleBot:Exception traceback:\n",
            "Traceback (most recent call last):\n",
            "  File \"/usr/local/lib/python3.10/dist-packages/telebot/__init__.py\", line 1074, in __threaded_polling\n",
            "    self.worker_pool.raise_exceptions()\n",
            "  File \"/usr/local/lib/python3.10/dist-packages/telebot/util.py\", line 147, in raise_exceptions\n",
            "    raise self.exception_info\n",
            "  File \"/usr/local/lib/python3.10/dist-packages/telebot/util.py\", line 90, in run\n",
            "    task(*args, **kwargs)\n",
            "  File \"/usr/local/lib/python3.10/dist-packages/telebot/__init__.py\", line 6720, in _run_middlewares_and_handler\n",
            "    result = handler['function'](message)\n",
            "  File \"<ipython-input-8-7f795ddbf42d>\", line 6, in url\n",
            "    bot.send_message(message.from_user.id, \"Привет , меня зовут Wiki! Если ты хочешь перейти в Русский Викисловарь, нажми на кнопку  ниже. Или введи любое слово чтобы узнать что это такое из энциклопедии! \", reply_markup = markup)\n",
            "  File \"/usr/local/lib/python3.10/dist-packages/telebot/__init__.py\", line 1549, in send_message\n",
            "    apihelper.send_message(\n",
            "  File \"/usr/local/lib/python3.10/dist-packages/telebot/apihelper.py\", line 264, in send_message\n",
            "    return _make_request(token, method_url, params=payload, method='post')\n",
            "  File \"/usr/local/lib/python3.10/dist-packages/telebot/apihelper.py\", line 162, in _make_request\n",
            "    json_result = _check_result(method_name, result)\n",
            "  File \"/usr/local/lib/python3.10/dist-packages/telebot/apihelper.py\", line 189, in _check_result\n",
            "    raise ApiTelegramException(method_name, result, result_json)\n",
            "telebot.apihelper.ApiTelegramException: A request to the Telegram API was unsuccessful. Error code: 403. Description: Forbidden: bot can't initiate conversation with a user\n",
            "\n",
            "2023-05-04 15:35:47,000 (__init__.py:1083 MainThread) ERROR - TeleBot: \"Threaded polling exception: A request to the Telegram API was unsuccessful. Error code: 403. Description: Forbidden: bot can't initiate conversation with a user\"\n",
            "ERROR:TeleBot:Threaded polling exception: A request to the Telegram API was unsuccessful. Error code: 403. Description: Forbidden: bot can't initiate conversation with a user\n",
            "2023-05-04 15:35:47,005 (__init__.py:1085 MainThread) ERROR - TeleBot: \"Exception traceback:\n",
            "Traceback (most recent call last):\n",
            "  File \"/usr/local/lib/python3.10/dist-packages/telebot/__init__.py\", line 1074, in __threaded_polling\n",
            "    self.worker_pool.raise_exceptions()\n",
            "  File \"/usr/local/lib/python3.10/dist-packages/telebot/util.py\", line 147, in raise_exceptions\n",
            "    raise self.exception_info\n",
            "  File \"/usr/local/lib/python3.10/dist-packages/telebot/util.py\", line 90, in run\n",
            "    task(*args, **kwargs)\n",
            "  File \"/usr/local/lib/python3.10/dist-packages/telebot/__init__.py\", line 6720, in _run_middlewares_and_handler\n",
            "    result = handler['function'](message)\n",
            "  File \"<ipython-input-8-7f795ddbf42d>\", line 6, in url\n",
            "    bot.send_message(message.from_user.id, \"Привет , меня зовут Wiki! Если ты хочешь перейти в Русский Викисловарь, нажми на кнопку  ниже. Или введи любое слово чтобы узнать что это такое из энциклопедии! \", reply_markup = markup)\n",
            "  File \"/usr/local/lib/python3.10/dist-packages/telebot/__init__.py\", line 1549, in send_message\n",
            "    apihelper.send_message(\n",
            "  File \"/usr/local/lib/python3.10/dist-packages/telebot/apihelper.py\", line 264, in send_message\n",
            "    return _make_request(token, method_url, params=payload, method='post')\n",
            "  File \"/usr/local/lib/python3.10/dist-packages/telebot/apihelper.py\", line 162, in _make_request\n",
            "    json_result = _check_result(method_name, result)\n",
            "  File \"/usr/local/lib/python3.10/dist-packages/telebot/apihelper.py\", line 189, in _check_result\n",
            "    raise ApiTelegramException(method_name, result, result_json)\n",
            "telebot.apihelper.ApiTelegramException: A request to the Telegram API was unsuccessful. Error code: 403. Description: Forbidden: bot can't initiate conversation with a user\n",
            "\"\n",
            "ERROR:TeleBot:Exception traceback:\n",
            "Traceback (most recent call last):\n",
            "  File \"/usr/local/lib/python3.10/dist-packages/telebot/__init__.py\", line 1074, in __threaded_polling\n",
            "    self.worker_pool.raise_exceptions()\n",
            "  File \"/usr/local/lib/python3.10/dist-packages/telebot/util.py\", line 147, in raise_exceptions\n",
            "    raise self.exception_info\n",
            "  File \"/usr/local/lib/python3.10/dist-packages/telebot/util.py\", line 90, in run\n",
            "    task(*args, **kwargs)\n",
            "  File \"/usr/local/lib/python3.10/dist-packages/telebot/__init__.py\", line 6720, in _run_middlewares_and_handler\n",
            "    result = handler['function'](message)\n",
            "  File \"<ipython-input-8-7f795ddbf42d>\", line 6, in url\n",
            "    bot.send_message(message.from_user.id, \"Привет , меня зовут Wiki! Если ты хочешь перейти в Русский Викисловарь, нажми на кнопку  ниже. Или введи любое слово чтобы узнать что это такое из энциклопедии! \", reply_markup = markup)\n",
            "  File \"/usr/local/lib/python3.10/dist-packages/telebot/__init__.py\", line 1549, in send_message\n",
            "    apihelper.send_message(\n",
            "  File \"/usr/local/lib/python3.10/dist-packages/telebot/apihelper.py\", line 264, in send_message\n",
            "    return _make_request(token, method_url, params=payload, method='post')\n",
            "  File \"/usr/local/lib/python3.10/dist-packages/telebot/apihelper.py\", line 162, in _make_request\n",
            "    json_result = _check_result(method_name, result)\n",
            "  File \"/usr/local/lib/python3.10/dist-packages/telebot/apihelper.py\", line 189, in _check_result\n",
            "    raise ApiTelegramException(method_name, result, result_json)\n",
            "telebot.apihelper.ApiTelegramException: A request to the Telegram API was unsuccessful. Error code: 403. Description: Forbidden: bot can't initiate conversation with a user\n",
            "\n",
            "2023-05-04 15:36:11,892 (__init__.py:1083 MainThread) ERROR - TeleBot: \"Threaded polling exception: A request to the Telegram API was unsuccessful. Error code: 403. Description: Forbidden: bot can't initiate conversation with a user\"\n",
            "ERROR:TeleBot:Threaded polling exception: A request to the Telegram API was unsuccessful. Error code: 403. Description: Forbidden: bot can't initiate conversation with a user\n",
            "2023-05-04 15:36:11,897 (__init__.py:1085 MainThread) ERROR - TeleBot: \"Exception traceback:\n",
            "Traceback (most recent call last):\n",
            "  File \"/usr/local/lib/python3.10/dist-packages/telebot/__init__.py\", line 1074, in __threaded_polling\n",
            "    self.worker_pool.raise_exceptions()\n",
            "  File \"/usr/local/lib/python3.10/dist-packages/telebot/util.py\", line 147, in raise_exceptions\n",
            "    raise self.exception_info\n",
            "  File \"/usr/local/lib/python3.10/dist-packages/telebot/util.py\", line 90, in run\n",
            "    task(*args, **kwargs)\n",
            "  File \"/usr/local/lib/python3.10/dist-packages/telebot/__init__.py\", line 6720, in _run_middlewares_and_handler\n",
            "    result = handler['function'](message)\n",
            "  File \"<ipython-input-8-7f795ddbf42d>\", line 6, in url\n",
            "    bot.send_message(message.from_user.id, \"Привет , меня зовут Wiki! Если ты хочешь перейти в Русский Викисловарь, нажми на кнопку  ниже. Или введи любое слово чтобы узнать что это такое из энциклопедии! \", reply_markup = markup)\n",
            "  File \"/usr/local/lib/python3.10/dist-packages/telebot/__init__.py\", line 1549, in send_message\n",
            "    apihelper.send_message(\n",
            "  File \"/usr/local/lib/python3.10/dist-packages/telebot/apihelper.py\", line 264, in send_message\n",
            "    return _make_request(token, method_url, params=payload, method='post')\n",
            "  File \"/usr/local/lib/python3.10/dist-packages/telebot/apihelper.py\", line 162, in _make_request\n",
            "    json_result = _check_result(method_name, result)\n",
            "  File \"/usr/local/lib/python3.10/dist-packages/telebot/apihelper.py\", line 189, in _check_result\n",
            "    raise ApiTelegramException(method_name, result, result_json)\n",
            "telebot.apihelper.ApiTelegramException: A request to the Telegram API was unsuccessful. Error code: 403. Description: Forbidden: bot can't initiate conversation with a user\n",
            "\"\n",
            "ERROR:TeleBot:Exception traceback:\n",
            "Traceback (most recent call last):\n",
            "  File \"/usr/local/lib/python3.10/dist-packages/telebot/__init__.py\", line 1074, in __threaded_polling\n",
            "    self.worker_pool.raise_exceptions()\n",
            "  File \"/usr/local/lib/python3.10/dist-packages/telebot/util.py\", line 147, in raise_exceptions\n",
            "    raise self.exception_info\n",
            "  File \"/usr/local/lib/python3.10/dist-packages/telebot/util.py\", line 90, in run\n",
            "    task(*args, **kwargs)\n",
            "  File \"/usr/local/lib/python3.10/dist-packages/telebot/__init__.py\", line 6720, in _run_middlewares_and_handler\n",
            "    result = handler['function'](message)\n",
            "  File \"<ipython-input-8-7f795ddbf42d>\", line 6, in url\n",
            "    bot.send_message(message.from_user.id, \"Привет , меня зовут Wiki! Если ты хочешь перейти в Русский Викисловарь, нажми на кнопку  ниже. Или введи любое слово чтобы узнать что это такое из энциклопедии! \", reply_markup = markup)\n",
            "  File \"/usr/local/lib/python3.10/dist-packages/telebot/__init__.py\", line 1549, in send_message\n",
            "    apihelper.send_message(\n",
            "  File \"/usr/local/lib/python3.10/dist-packages/telebot/apihelper.py\", line 264, in send_message\n",
            "    return _make_request(token, method_url, params=payload, method='post')\n",
            "  File \"/usr/local/lib/python3.10/dist-packages/telebot/apihelper.py\", line 162, in _make_request\n",
            "    json_result = _check_result(method_name, result)\n",
            "  File \"/usr/local/lib/python3.10/dist-packages/telebot/apihelper.py\", line 189, in _check_result\n",
            "    raise ApiTelegramException(method_name, result, result_json)\n",
            "telebot.apihelper.ApiTelegramException: A request to the Telegram API was unsuccessful. Error code: 403. Description: Forbidden: bot can't initiate conversation with a user\n",
            "\n",
            "2023-05-04 15:36:23,968 (__init__.py:1083 MainThread) ERROR - TeleBot: \"Threaded polling exception: A request to the Telegram API was unsuccessful. Error code: 403. Description: Forbidden: bot can't initiate conversation with a user\"\n",
            "ERROR:TeleBot:Threaded polling exception: A request to the Telegram API was unsuccessful. Error code: 403. Description: Forbidden: bot can't initiate conversation with a user\n",
            "2023-05-04 15:36:23,970 (__init__.py:1085 MainThread) ERROR - TeleBot: \"Exception traceback:\n",
            "Traceback (most recent call last):\n",
            "  File \"/usr/local/lib/python3.10/dist-packages/telebot/__init__.py\", line 1074, in __threaded_polling\n",
            "    self.worker_pool.raise_exceptions()\n",
            "  File \"/usr/local/lib/python3.10/dist-packages/telebot/util.py\", line 147, in raise_exceptions\n",
            "    raise self.exception_info\n",
            "  File \"/usr/local/lib/python3.10/dist-packages/telebot/util.py\", line 90, in run\n",
            "    task(*args, **kwargs)\n",
            "  File \"/usr/local/lib/python3.10/dist-packages/telebot/__init__.py\", line 6720, in _run_middlewares_and_handler\n",
            "    result = handler['function'](message)\n",
            "  File \"<ipython-input-8-7f795ddbf42d>\", line 6, in url\n",
            "    bot.send_message(message.from_user.id, \"Привет , меня зовут Wiki! Если ты хочешь перейти в Русский Викисловарь, нажми на кнопку  ниже. Или введи любое слово чтобы узнать что это такое из энциклопедии! \", reply_markup = markup)\n",
            "  File \"/usr/local/lib/python3.10/dist-packages/telebot/__init__.py\", line 1549, in send_message\n",
            "    apihelper.send_message(\n",
            "  File \"/usr/local/lib/python3.10/dist-packages/telebot/apihelper.py\", line 264, in send_message\n",
            "    return _make_request(token, method_url, params=payload, method='post')\n",
            "  File \"/usr/local/lib/python3.10/dist-packages/telebot/apihelper.py\", line 162, in _make_request\n",
            "    json_result = _check_result(method_name, result)\n",
            "  File \"/usr/local/lib/python3.10/dist-packages/telebot/apihelper.py\", line 189, in _check_result\n",
            "    raise ApiTelegramException(method_name, result, result_json)\n",
            "telebot.apihelper.ApiTelegramException: A request to the Telegram API was unsuccessful. Error code: 403. Description: Forbidden: bot can't initiate conversation with a user\n",
            "\"\n",
            "ERROR:TeleBot:Exception traceback:\n",
            "Traceback (most recent call last):\n",
            "  File \"/usr/local/lib/python3.10/dist-packages/telebot/__init__.py\", line 1074, in __threaded_polling\n",
            "    self.worker_pool.raise_exceptions()\n",
            "  File \"/usr/local/lib/python3.10/dist-packages/telebot/util.py\", line 147, in raise_exceptions\n",
            "    raise self.exception_info\n",
            "  File \"/usr/local/lib/python3.10/dist-packages/telebot/util.py\", line 90, in run\n",
            "    task(*args, **kwargs)\n",
            "  File \"/usr/local/lib/python3.10/dist-packages/telebot/__init__.py\", line 6720, in _run_middlewares_and_handler\n",
            "    result = handler['function'](message)\n",
            "  File \"<ipython-input-8-7f795ddbf42d>\", line 6, in url\n",
            "    bot.send_message(message.from_user.id, \"Привет , меня зовут Wiki! Если ты хочешь перейти в Русский Викисловарь, нажми на кнопку  ниже. Или введи любое слово чтобы узнать что это такое из энциклопедии! \", reply_markup = markup)\n",
            "  File \"/usr/local/lib/python3.10/dist-packages/telebot/__init__.py\", line 1549, in send_message\n",
            "    apihelper.send_message(\n",
            "  File \"/usr/local/lib/python3.10/dist-packages/telebot/apihelper.py\", line 264, in send_message\n",
            "    return _make_request(token, method_url, params=payload, method='post')\n",
            "  File \"/usr/local/lib/python3.10/dist-packages/telebot/apihelper.py\", line 162, in _make_request\n",
            "    json_result = _check_result(method_name, result)\n",
            "  File \"/usr/local/lib/python3.10/dist-packages/telebot/apihelper.py\", line 189, in _check_result\n",
            "    raise ApiTelegramException(method_name, result, result_json)\n",
            "telebot.apihelper.ApiTelegramException: A request to the Telegram API was unsuccessful. Error code: 403. Description: Forbidden: bot can't initiate conversation with a user\n",
            "\n",
            "2023-05-04 15:42:38,509 (__init__.py:1083 MainThread) ERROR - TeleBot: \"Threaded polling exception: A request to the Telegram API was unsuccessful. Error code: 403. Description: Forbidden: bot can't initiate conversation with a user\"\n",
            "ERROR:TeleBot:Threaded polling exception: A request to the Telegram API was unsuccessful. Error code: 403. Description: Forbidden: bot can't initiate conversation with a user\n",
            "2023-05-04 15:42:38,513 (__init__.py:1085 MainThread) ERROR - TeleBot: \"Exception traceback:\n",
            "Traceback (most recent call last):\n",
            "  File \"/usr/local/lib/python3.10/dist-packages/telebot/__init__.py\", line 1074, in __threaded_polling\n",
            "    self.worker_pool.raise_exceptions()\n",
            "  File \"/usr/local/lib/python3.10/dist-packages/telebot/util.py\", line 147, in raise_exceptions\n",
            "    raise self.exception_info\n",
            "  File \"/usr/local/lib/python3.10/dist-packages/telebot/util.py\", line 90, in run\n",
            "    task(*args, **kwargs)\n",
            "  File \"/usr/local/lib/python3.10/dist-packages/telebot/__init__.py\", line 6720, in _run_middlewares_and_handler\n",
            "    result = handler['function'](message)\n",
            "  File \"<ipython-input-8-7f795ddbf42d>\", line 6, in url\n",
            "    bot.send_message(message.from_user.id, \"Привет , меня зовут Wiki! Если ты хочешь перейти в Русский Викисловарь, нажми на кнопку  ниже. Или введи любое слово чтобы узнать что это такое из энциклопедии! \", reply_markup = markup)\n",
            "  File \"/usr/local/lib/python3.10/dist-packages/telebot/__init__.py\", line 1549, in send_message\n",
            "    apihelper.send_message(\n",
            "  File \"/usr/local/lib/python3.10/dist-packages/telebot/apihelper.py\", line 264, in send_message\n",
            "    return _make_request(token, method_url, params=payload, method='post')\n",
            "  File \"/usr/local/lib/python3.10/dist-packages/telebot/apihelper.py\", line 162, in _make_request\n",
            "    json_result = _check_result(method_name, result)\n",
            "  File \"/usr/local/lib/python3.10/dist-packages/telebot/apihelper.py\", line 189, in _check_result\n",
            "    raise ApiTelegramException(method_name, result, result_json)\n",
            "telebot.apihelper.ApiTelegramException: A request to the Telegram API was unsuccessful. Error code: 403. Description: Forbidden: bot can't initiate conversation with a user\n",
            "\"\n",
            "ERROR:TeleBot:Exception traceback:\n",
            "Traceback (most recent call last):\n",
            "  File \"/usr/local/lib/python3.10/dist-packages/telebot/__init__.py\", line 1074, in __threaded_polling\n",
            "    self.worker_pool.raise_exceptions()\n",
            "  File \"/usr/local/lib/python3.10/dist-packages/telebot/util.py\", line 147, in raise_exceptions\n",
            "    raise self.exception_info\n",
            "  File \"/usr/local/lib/python3.10/dist-packages/telebot/util.py\", line 90, in run\n",
            "    task(*args, **kwargs)\n",
            "  File \"/usr/local/lib/python3.10/dist-packages/telebot/__init__.py\", line 6720, in _run_middlewares_and_handler\n",
            "    result = handler['function'](message)\n",
            "  File \"<ipython-input-8-7f795ddbf42d>\", line 6, in url\n",
            "    bot.send_message(message.from_user.id, \"Привет , меня зовут Wiki! Если ты хочешь перейти в Русский Викисловарь, нажми на кнопку  ниже. Или введи любое слово чтобы узнать что это такое из энциклопедии! \", reply_markup = markup)\n",
            "  File \"/usr/local/lib/python3.10/dist-packages/telebot/__init__.py\", line 1549, in send_message\n",
            "    apihelper.send_message(\n",
            "  File \"/usr/local/lib/python3.10/dist-packages/telebot/apihelper.py\", line 264, in send_message\n",
            "    return _make_request(token, method_url, params=payload, method='post')\n",
            "  File \"/usr/local/lib/python3.10/dist-packages/telebot/apihelper.py\", line 162, in _make_request\n",
            "    json_result = _check_result(method_name, result)\n",
            "  File \"/usr/local/lib/python3.10/dist-packages/telebot/apihelper.py\", line 189, in _check_result\n",
            "    raise ApiTelegramException(method_name, result, result_json)\n",
            "telebot.apihelper.ApiTelegramException: A request to the Telegram API was unsuccessful. Error code: 403. Description: Forbidden: bot can't initiate conversation with a user\n",
            "\n"
          ]
        }
      ],
      "source": [
        "def getwiki(s):\n",
        "\n",
        "    try:\n",
        "\n",
        "        ny = wikipedia.page(s)\n",
        "\n",
        "        # Получаем первую тысячу символов\n",
        "\n",
        "        wikitext=ny.content[:1000]\n",
        "\n",
        "        # Разбиваем, считая точку разделителем\n",
        "\n",
        "        wikimas=wikitext.split('.')\n",
        "\n",
        "        # Отбрасываем всё после последней точки\n",
        "\n",
        "        wikimas = wikimas[:-1]\n",
        "\n",
        "        # Создаем пустую переменную для текста\n",
        "\n",
        "        wikitext2 = ''\n",
        "\n",
        "        # Проходимся по строкам, где нет знаков «равно» (то есть все, кроме заголовков)\n",
        "\n",
        "        for x in wikimas:\n",
        "\n",
        "            if not('==' in x):\n",
        "\n",
        "                    # Если в строке осталось больше трех символов, добавляем ее\n",
        "\n",
        "                    # к нашей переменной и возвращаем утерянные при разделении строк точки на место\n",
        "\n",
        "                if(len((x.strip()))>3):\n",
        "\n",
        "                   wikitext2=wikitext2+x+'.'\n",
        "\n",
        "            else:\n",
        "\n",
        "                break\n",
        "\n",
        "        # Теперь при помощи регулярных выражений убираем разметку\n",
        "\n",
        "        wikitext2=re.sub('\\([^()]*\\)', '', wikitext2)\n",
        "\n",
        "        wikitext2=re.sub('\\([^()]*\\)', '', wikitext2)\n",
        "\n",
        "        wikitext2=re.sub('\\{[^\\{\\}]*\\}', '', wikitext2)\n",
        "\n",
        "        # Возвращаем текстовую строку\n",
        "\n",
        "        return wikitext2\n",
        "\n",
        "    # Обрабатываем исключение, которое мог вернуть модуль wikipedia при запросе\n",
        "\n",
        "    except Exception as e:\n",
        "\n",
        "        return 'Попробуй задать вопрос по другому , я не нашла ответ'\n",
        "\n",
        "# Функция, обрабатывающая команду /start\n",
        "\n",
        "@bot.message_handler(commands=[\"start\"])\n",
        "\n",
        "def start(m, res=False):\n",
        "\n",
        "    bot.send_message(m.chat.id, 'Введите любое слово, чтобы я ответила!')\n",
        "\n",
        "# Получение сообщений от пользователя\n",
        "\n",
        "@bot.message_handler(content_types=[\"text\"])\n",
        "\n",
        "def handle_text(message):\n",
        "\n",
        "    bot.send_message(message.chat.id, getwiki(message.text))\n",
        "\n",
        "# Запускаем бота\n",
        "\n",
        "bot.polling(none_stop=True, interval=0)"
      ]
    }
  ],
  "metadata": {
    "colab": {
      "provenance": []
    },
    "kernelspec": {
      "display_name": "Python 3",
      "name": "python3"
    },
    "language_info": {
      "name": "python"
    }
  },
  "nbformat": 4,
  "nbformat_minor": 0
}